Workbook

Sheet Dataset
A1: Customer ID | B1: First Name | C1: Last Name | D1: Age | E1: Gender | F1: Account Type | G1: Account Balance$ | H1: Annual Income$ | I1: Loan Status | J1: Loan Amount | K1: Credit Score | L1: Investment Type | M1: Credit Card Offers | N1: Online Banking Status | O1: Interest rate | P1: EASY | Q1: Ans-7 | R1: income loan ratio | S1: ERROR | T1: Ans-8 | U1: ISNUMBER | V1: Ans-9 | W1: age distribution | X1: Ans-11 | Y1: RANK | Z1: MEDIUM | AA1: ANS-8 | AB1: GOOD/BAD USERS | AD1: Ans-9 | AE1: ISERROR | AF1: ANS-10 | AG1: ISTEXT | AH1: ANS-11 | AI1: Active/inactive consumer | AL1: HARD | AM1: ANS-2 | AN1: Eligible/not_eligible | AP1: ANS-4 | AQ1: GOOD/BAD CLIENT | AS1: ANS-5 | AT1: eligible ref Q2 | AU1: Saving acc&credit card | AW1: ANS-6 | AX1: all credit card accepted | AY1: GOOD/BAD USERS | AZ1: Inprogress/not_inprogress | BC1: ANS-12 | BD1: income above 6k
A2: 1 | B2: John | C2: Doe | D2: 24 | E2: M | F2: Checking | G2: 2500 | H2: 55000 | I2: No | J2: 0 | K2: 720 | L2: Stocks | M2: Premium | N2: Active | O2: 7 | R2: =H2/J2 -> #DIV/0! | S2: =IFERROR(R2,"DIVISION ERROR") -> DIVISION ERROR | U2: {=ISNUMBER(S2:S350)} -> FALSE | W2: =IF(ISODD(D2),"ODD","EVEN") -> EVEN | X2: =_xlfn.RANK.AVG(K2,$K$2:$K$350,0) -> 60 | AA2: =IF(N2="Active","Good_user","Bad_user") -> Good_user | AD2: =ISERROR(R2) -> TRUE | AF2: =ISTEXT(O2) -> FALSE | AH2: =IF(AND(Dataset!G2 >5000,Dataset!H2>7000),"ACTIVE_CONSUMER","INACTIVE_CONSUMER") -> INACTIVE_CONSUMER | AM2: =IF(AND(D2>40,H2<8000,K2<300),"Eligible","Not_eligible") -> Not_eligible | AP2: =IF(AND(E2="M",F2="checking",Dataset!G2>2000,Dataset!K2>500),"good_client","bad_client") -> good_client | AS2: Not_eligible | AT2: =IF(AND(Dataset!F2="Savings",Dataset!AS2="eligible"),"YES","NO") -> NO | AW2: yes | AX2: Good_user | AY2: =IF(AND(AW2="yes",AX2="Good_user"),"inprogress","not_inprogress") -> not_inprogress | BC2: =IF(H2>6000,"yes","no") -> yes
A3: 2 | B3: Jane | C3: Smith | D3: 29 | E3: F | F3: Savings | G3: 8000 | H3: 62000 | I3: Yes | J3: 15000 | K3: 680 | L3: Bonds | M3: standard | N3: Inactive | O3: 5 | R3: =H3/J3 -> 4.1333333 | S3: =IFERROR(R3,"DIVISION ERROR") -> 4.1333333 | U3: TRUE | W3: =IF(ISODD(D3),"ODD","EVEN") -> ODD | X3: =_xlfn.RANK.AVG(K3,$K$2:$K$350,0) -> 286 | AA3: =IF(N3="Active","Good_user","Bad_user") -> Bad_user | AD3: =ISERROR(R3) -> FALSE | AF3: =ISTEXT(O3) -> FALSE | AH3: =IF(AND(Dataset!G3 >5000,Dataset!H3>7000),"ACTIVE_CONSUMER","INACTIVE_CONSUMER") -> ACTIVE_CONSUMER | AM3: =IF(AND(D3>40,H3<8000,K3<300),"Eligible","Not_eligible") -> Not_eligible | AP3: =IF(AND(E3="M",F3="checking",Dataset!G3>2000,Dataset!K3>500),"good_client","bad_client") -> bad_client | AS3: Not_eligible | AT3: =IF(AND(Dataset!F3="Savings",Dataset!AS3="eligible"),"YES","NO") -> NO | AW3: yes | AX3: Bad_user | BC3: =IF(H3>6000,"yes","no") -> yes
A4: 3 | B4: Emily | C4: Johnson | D4: 45 | E4: F | F4: Checking | G4: 12000 | H4: 75000 | I4: No | J4: 0 | K4: 750 | L4: Mutual Funds | M4: none | N4: Active | O4: 3 | R4: =H4/J4 -> #DIV/0! | S4: =IFERROR(R4,"DIVISION ERROR") -> DIVISION ERROR | U4: FALSE | W4: =IF(ISODD(D4),"ODD","EVEN") -> ODD | X4: =_xlfn.RANK.AVG(K4,$K$2:$K$350,0) -> 3 | AA4: =IF(N4="Active","Good_user","Bad_user") -> Good_user | AD4: =ISERROR(R4) -> TRUE | AF4: =ISTEXT(O4) -> FALSE | AH4: =IF(AND(Dataset!G4 >5000,Dataset!H4>7000),"ACTIVE_CONSUMER","INACTIVE_CONSUMER") -> ACTIVE_CONSUMER | AM4: =IF(AND(D4>40,H4<8000,K4<300),"Eligible","Not_eligible") -> Not_eligible | AP4: =IF(AND(E4="M",F4="checking",Dataset!G4>2000,Dataset!K4>500),"good_client","bad_client") -> bad_client | AS4: Not_eligible | AT4: =IF(AND(Dataset!F4="Savings",Dataset!AS4="eligible"),"YES","NO") -> NO | AW4: no | AX4: Good_user | BC4: =IF(H4>6000,"yes","no") -> yes
A5: 4 | B5: Michael | C5: Brown | D5: 52 | E5: M | F5: Savings | G5: 3000 | H5: 48000 | I5: Yes | J5: 5000 | K5: 690 | L5: Real Estate | M5: Premium | N5: Active | O5: 3 | R5: =H5/J5 -> 9.6 | S5: =IFERROR(R5,"DIVISION ERROR") -> 9.6 | U5: TRUE | W5: =IF(ISODD(D5),"ODD","EVEN") -> EVEN | X5: =_xlfn.RANK.AVG(K5,$K$2:$K$350,0) -> 223.5 | AA5: =IF(N5="Active","Good_user","Bad_user") -> Good_user | AD5: =ISERROR(R5) -> FALSE | AF5: =ISTEXT(O5) -> FALSE | AH5: =IF(AND(Dataset!G5 >5000,Dataset!H5>7000),"ACTIVE_CONSUMER","INACTIVE_CONSUMER") -> INACTIVE_CONSUMER | AM5: =IF(AND(D5>40,H5<8000,K5<300),"Eligible","Not_eligible") -> Not_eligible | AP5: =IF(AND(E5="M",F5="checking",Dataset!G5>2000,Dataset!K5>500),"good_client","bad_client") -> bad_client | AS5: Not_eligible | AT5: =IF(AND(Dataset!F5="Savings",Dataset!AS5="eligible"),"YES","NO") -> NO | AW5: yes | AX5: Good_user | BC5: =IF(H5>6000,"yes","no") -> yes
A6: 5 | B6: Sarah | C6: Davis | D6: 37 | E6: F | F6: Checking | G6: 5000 | H6: 58000 | I6: No | J6: 0 | K6: 710 | L6: Stocks | M6: Premium | N6: Inactive | O6: 4 | R6: =H6/J6 -> #DIV/0! | S6: =IFERROR(R6,"DIVISION ERROR") -> DIVISION ERROR | U6: FALSE | W6: =IF(ISODD(D6),"ODD","EVEN") -> ODD | X6: =_xlfn.RANK.AVG(K6,$K$2:$K$350,0) -> 120.5 | AA6: =IF(N6="Active","Good_user","Bad_user") -> Bad_user | AD6: =ISERROR(R6) -> TRUE | AF6: =ISTEXT(O6) -> FALSE | AH6: =IF(AND(Dataset!G6 >5000,Dataset!H6>7000),"ACTIVE_CONSUMER","INACTIVE_CONSUMER") -> INACTIVE_CONSUMER | AM6: =IF(AND(D6>40,H6<8000,K6<300),"Eligible","Not_eligible") -> Not_eligible | AP6: =IF(AND(E6="M",F6="checking",Dataset!G6>2000,Dataset!K6>500),"good_client","bad_client") -> bad_client | AS6: Not_eligible | AT6: =IF(AND(Dataset!F6="Savings",Dataset!AS6="eligible"),"YES","NO") -> NO | AW6: yes | AX6: Bad_user | BC6: =IF(H6>6000,"yes","no") -> yes
A7: 6 | B7: William | C7: Martinez | D7: 30 | E7: M | F7: Savings | G7: 6000 | H7: 70000 | I7: Yes | J7: 20000 | K7: 700 | L7: Bonds | M7: Premium | N7: Active | O7: 3 | R7: =H7/J7 -> 3.5 | S7: =IFERROR(R7,"DIVISION ERROR") -> 3.5 | U7: TRUE | W7: =IF(ISODD(D7),"ODD","EVEN") -> EVEN | X7: =_xlfn.RANK.AVG(K7,$K$2:$K$350,0) -> 170 | AA7: =IF(N7="Active","Good_user","Bad_user") -> Good_user | AD7: =ISERROR(R7) -> FALSE | AF7: =ISTEXT(O7) -> FALSE | AH7: =IF(AND(Dataset!G7 >5000,Dataset!H7>7000),"ACTIVE_CONSUMER","INACTIVE_CONSUMER") -> ACTIVE_CONSUMER | AM7: =IF(AND(D7>40,H7<8000,K7<300),"Eligible","Not_eligible") -> Not_eligible | AP7: =IF(AND(E7="M",F7="checking",Dataset!G7>2000,Dataset!K7>500),"good_client","bad_client") -> bad_client | AS7: Not_eligible | AT7: =IF(AND(Dataset!F7="Savings",Dataset!AS7="eligible"),"YES","NO") -> NO | AW7: yes | AX7: Good_user | BC7: =IF(H7>6000,"yes","no") -> yes
A8: 7 | B8: Olivia | C8: Lee | D8: 40 | E8: F | F8: Checking | G8: 15000 | H8: 82000 | I8: No | J8: 0 | K8: 730 | L8: Mutual Funds | M8: Premium | N8: Inactive | O8: 7 | R8: =H8/J8 -> #DIV/0! | S8: =IFERROR(R8,"DIVISION ERROR") -> DIVISION ERROR | U8: FALSE | W8: =IF(ISODD(D8),"ODD","EVEN") -> EVEN | X8: =_xlfn.RANK.AVG(K8,$K$2:$K$350,0) -> 23 | AA8: =IF(N8="Active","Good_user","Bad_user") -> Bad_user | AD8: =ISERROR(R8) -> TRUE | AF8: =ISTEXT(O8) -> FALSE | AH8: =IF(AND(Dataset!G8 >5000,Dataset!H8>7000),"ACTIVE_CONSUMER","INACTIVE_CONSUMER") -> ACTIVE_CONSUMER | AM8: =IF(AND(D8>40,H8<8000,K8<300),"Eligible","Not_eligible") -> Not_eligible | AP8: =IF(AND(E8="M",F8="checking",Dataset!G8>2000,Dataset!K8>500),"good_client","bad_client") -> bad_client | AS8: Not_eligible | AT8: =IF(AND(Dataset!F8="Savings",Dataset!AS8="eligible"),"YES","NO") -> NO | AW8: yes | AX8: Bad_user | BC8: =IF(H8>6000,"yes","no") -> yes
A9: 8 | B9: James | C9: Wilson | D9: 25 | E9: M | F9: Savings | G9: 2000 | H9: 43000 | I9: No | J9: 0 | K9: 670 | L9: Real Estate | M9: standard | N9: Active | O9: 12 | R9: =H9/J9 -> #DIV/0! | S9: =IFERROR(R9,"DIVISION ERROR") -> DIVISION ERROR | U9: FALSE | W9: =IF(ISODD(D9),"ODD","EVEN") -> ODD | X9: =_xlfn.RANK.AVG(K9,$K$2:$K$350,0) -> 334 | AA9: =IF(N9="Active","Good_user","Bad_user") -> Good_user | AD9: =ISERROR(R9) -> TRUE | AF9: =ISTEXT(O9) -> FALSE | AH9: =IF(AND(Dataset!G9 >5000,Dataset!H9>7000),"ACTIVE_CONSUMER","INACTIVE_CONSUMER") -> INACTIVE_CONSUMER | AM9: =IF(AND(D9>40,H9<8000,K9<300),"Eligible","Not_eligible") -> Not_eligible | AP9: =IF(AND(E9="M",F9="checking",Dataset!G9>2000,Dataset!K9>500),"good_client","bad_client") -> bad_client | AS9: Not_eligible | AT9: =IF(AND(Dataset!F9="Savings",Dataset!AS9="eligible"),"YES","NO") -> NO | AW9: yes | AX9: Good_user | BC9: =IF(H9>6000,"yes","no") -> yes
A10: 9 | B10: Ava | C10: Anderson | D10: 31 | E10: F | F10: Checking | G10: 7000 | H10: 55000 | I10: Yes | J10: 10000 | K10: 720 | L10: Stocks | M10: standard | N10: Active | O10: 11 | R10: =H10/J10 -> 5.5 | S10: =IFERROR(R10,"DIVISION ERROR") -> 5.5 | U10: TRUE | W10: =IF(ISODD(D10),"ODD","EVEN") -> ODD | X10: =_xlfn.RANK.AVG(K10,$K$2:$K$350,0) -> 60 | AA10: =IF(N10="Active","Good_user","Bad_user") -> Good_user | AD10: =ISERROR(R10) -> FALSE | AF10: =ISTEXT(O10) -> FALSE | AH10: =IF(AND(Dataset!G10 >5000,Dataset!H10>7000),"ACTIVE_CONSUMER","INACTIVE_CONSUMER") -> ACTIVE_CONSUMER | AM10: =IF(AND(D10>40,H10<8000,K10<300),"Eligible","Not_eligible") -> Not_eligible | AP10: =IF(AND(E10="M",F10="checking",Dataset!G10>2000,Dataset!K10>500),"good_client","bad_client") -> bad_client | AS10: Not_eligible | AT10: =IF(AND(Dataset!F10="Savings",Dataset!AS10="eligible"),"YES","NO") -> NO | AW10: yes | AX10: Good_user | BC10: =IF(H10>6000,"yes","no") -> yes
A11: 10 | B11: Ethan | C11: Thomas | D11: 44 | E11: M | F11: Savings | G11: 11000 | H11: 65000 | I11: No | J11: 0 | K11: 740 | L11: Bonds | M11: none | N11: Inactive | O11: 3 | R11: =H11/J11 -> #DIV/0! | S11: =IFERROR(R11,"DIVISION ERROR") -> DIVISION ERROR | U11: FALSE | W11: =IF(ISODD(D11),"ODD","EVEN") -> EVEN | X11: =_xlfn.RANK.AVG(K11,$K$2:$K$350,0) -> 13 | AA11: =IF(N11="Active","Good_user","Bad_user") -> Bad_user | AD11: =ISERROR(R11) -> TRUE | AF11: =ISTEXT(O11) -> FALSE | AH11: =IF(AND(Dataset!G11 >5000,Dataset!H11>7000),"ACTIVE_CONSUMER","INACTIVE_CONSUMER") -> ACTIVE_CONSUMER | AM11: =IF(AND(D11>40,H11<8000,K11<300),"Eligible","Not_eligible") -> Not_eligible | AP11: =IF(AND(E11="M",F11="checking",Dataset!G11>2000,Dataset!K11>500),"good_client","bad_client") -> bad_client | AS11: Not_eligible | AT11: =IF(AND(Dataset!F11="Savings",Dataset!AS11="eligible"),"YES","NO") -> NO | AW11: no | AX11: Bad_user | BC11: =IF(H11>6000,"yes","no") -> yes
A12: 11 | B12: Isabella | C12: White | D12: 28 | E12: F | F12: Checking | G12: 4500 | H12: 47000 | I12: No | J12: 0 | K12: 690 | L12: Mutual Funds | M12: Premium | N12: Active | O12: 3 | R12: =H12/J12 -> #DIV/0! | S12: =IFERROR(R12,"DIVISION ERROR") -> DIVISION ERROR | U12: FALSE | W12: =IF(ISODD(D12),"ODD","EVEN") -> EVEN | X12: =_xlfn.RANK.AVG(K12,$K$2:$K$350,0) -> 223.5 | AA12: =IF(N12="Active","Good_user","Bad_user") -> Good_user | AD12: =ISERROR(R12) -> TRUE | AF12: =ISTEXT(O12) -> FALSE | AH12: =IF(AND(Dataset!G12 >5000,Dataset!H12>7000),"ACTIVE_CONSUMER","INACTIVE_CONSUMER") -> INACTIVE_CONSUMER | AM12: =IF(AND(D12>40,H12<8000,K12<300),"Eligible","Not_eligible") -> Not_eligible | AP12: =IF(AND(E12="M",F12="checking",Dataset!G12>2000,Dataset!K12>500),"good_client","bad_client") -> bad_client | AS12: Not_eligible | AT12: =IF(AND(Dataset!F12="Savings",Dataset!AS12="eligible"),"YES","NO") -> NO | AW12: yes | AX12: Good_user | BC12: =IF(H12>6000,"yes","no") -> yes
A13: 12 | B13: Benjamin | C13: Harris | D13: 39 | E13: M | F13: Savings | G13: 10000 | H13: 72000 | I13: Yes | J13: 12000 | K13: 700 | L13: Real Estate | M13: none | N13: Active | O13: No loan | R13: =H13/J13 -> 6 | S13: =IFERROR(R13,"DIVISION ERROR") -> 6 | U13: TRUE | W13: =IF(ISODD(D13),"ODD","EVEN") -> ODD | X13: =_xlfn.RANK.AVG(K13,$K$2:$K$350,0) -> 170 | AA13: =IF(N13="Active","Good_user","Bad_user") -> Good_user | AD13: =ISERROR(R13) -> FALSE | AF13: =ISTEXT(O13) -> TRUE | AH13: =IF(AND(Dataset!G13 >5000,Dataset!H13>7000),"ACTIVE_CONSUMER","INACTIVE_CONSUMER") -> ACTIVE_CONSUMER | AM13: =IF(AND(D13>40,H13<8000,K13<300),"Eligible","Not_eligible") -> Not_eligible | AP13: =IF(AND(E13="M",F13="checking",Dataset!G13>2000,Dataset!K13>500),"good_client","bad_client") -> bad_client | AS13: Not_eligible | AT13: =IF(AND(Dataset!F13="Savings",Dataset!AS13="eligible"),"YES","NO") -> NO | AW13: ` | AX13: Good_user | BC13: =IF(H13>6000,"yes","no") -> yes
A14: 13 | B14: Mia | C14: Clark | D14: 26 | E14: F | F14: Checking | G14: 3500 | H14: 53000 | I14: No | J14: 0 | K14: 680 | L14: Stocks | M14: standard | N14: Inactive | O14: 11 | R14: =H14/J14 -> #DIV/0! | S14: =IFERROR(R14,"DIVISION ERROR") -> DIVISION ERROR | U14: FALSE | W14: =IF(ISODD(D14),"ODD","EVEN") -> EVEN | X14: =_xlfn.RANK.AVG(K14,$K$2:$K$350,0) -> 286 | AA14: =IF(N14="Active","Good_user","Bad_user") -> Bad_user | AD14: =ISERROR(R14) -> TRUE | AF14: =ISTEXT(O14) -> FALSE | AH14: =IF(AND(Dataset!G14 >5000,Dataset!H14>7000),"ACTIVE_CONSUMER","INACTIVE_CONSUMER") -> INACTIVE_CONSUMER | AM14: =IF(AND(D14>40,H14<8000,K14<300),"Eligible","Not_eligible") -> Not_eligible | AP14: =IF(AND(E14="M",F14="checking",Dataset!G14>2000,Dataset!K14>500),"good_client","bad_client") -> bad_client | AS14: Not_eligible | AT14: =IF(AND(Dataset!F14="Savings",Dataset!AS14="eligible"),"YES","NO") -> NO | AW14: yes | AX14: Bad_user | BC14: =IF(H14>6000,"yes","no") -> yes
A15: 14 | B15: Jacob | C15: Lewis | D15: 33 | E15: M | F15: Savings | G15: 8000 | H15: 60000 | I15: Yes | J15: 8000 | K15: 710 | L15: Bonds | M15: Premium | N15: Active | O15: 11 | R15: =H15/J15 -> 7.5 | S15: =IFERROR(R15,"DIVISION ERROR") -> 7.5 | U15: TRUE | W15: =IF(ISODD(D15),"ODD","EVEN") -> ODD | X15: =_xlfn.RANK.AVG(K15,$K$2:$K$350,0) -> 120.5 | AA15: =IF(N15="Active","Good_user","Bad_user") -> Good_user | AD15: =ISERROR(R15) -> FALSE | AF15: =ISTEXT(O15) -> FALSE | AH15: =IF(AND(Dataset!G15 >5000,Dataset!H15>7000),"ACTIVE_CONSUMER","INACTIVE_CONSUMER") -> ACTIVE_CONSUMER | AM15: =IF(AND(D15>40,H15<8000,K15<300),"Eligible","Not_eligible") -> Not_eligible | AP15: =IF(AND(E15="M",F15="checking",Dataset!G15>2000,Dataset!K15>500),"good_client","bad_client") -> bad_client | AS15: Not_eligible | AT15: =IF(AND(Dataset!F15="Savings",Dataset!AS15="eligible"),"YES","NO") -> NO | AW15: yes | AX15: Good_user | BC15: =IF(H15>6000,"yes","no") -> yes
A16: 15 | B16: Charlotte | C16: Walker | D16: 46 | E16: F | F16: Checking | G16: 13000 | H16: 85000 | I16: No | J16: 0 | K16: 740 | L16: Mutual Funds | M16: none | N16: Inactive | O16: 6 | R16: =H16/J16 -> #DIV/0! | S16: =IFERROR(R16,"DIVISION ERROR") -> DIVISION ERROR | U16: FALSE | W16: =IF(ISODD(D16),"ODD","EVEN") -> EVEN | X16: =_xlfn.RANK.AVG(K16,$K$2:$K$350,0) -> 13 | AA16: =IF(N16="Active","Good_user","Bad_user") -> Bad_user | AD16: =ISERROR(R16) -> TRUE | AF16: =ISTEXT(O16) -> FALSE | AH16: =IF(AND(Dataset!G16 >5000,Dataset!H16>7000),"ACTIVE_CONSUMER","INACTIVE_CONSUMER") -> ACTIVE_CONSUMER | AM16: =IF(AND(D16>40,H16<8000,K16<300),"Eligible","Not_eligible") -> Not_eligible | AP16: =IF(AND(E16="M",F16="checking",Dataset!G16>2000,Dataset!K16>500),"good_client","bad_client") -> bad_client | AS16: Not_eligible | AT16: =IF(AND(Dataset!F16="Savings",Dataset!AS16="eligible"),"YES","NO") -> NO | AW16: no | AX16: Bad_user | BC16: =IF(H16>6000,"yes","no") -> yes
A17: 16 | B17: Daniel | C17: Hall | D17: 52 | E17: M | F17: Savings | G17: 4000 | H17: 49000 | I17: Yes | J17: 7000 | K17: 690 | L17: Real Estate | M17: Premium | N17: Active | O17: 6 | R17: =H17/J17 -> 7 | S17: =IFERROR(R17,"DIVISION ERROR") -> 7 | U17: TRUE | W17: =IF(ISODD(D17),"ODD","EVEN") -> EVEN | X17: =_xlfn.RANK.AVG(K17,$K$2:$K$350,0) -> 223.5 | AA17: =IF(N17="Active","Good_user","Bad_user") -> Good_user | AD17: =ISERROR(R17) -> FALSE | AF17: =ISTEXT(O17) -> FALSE | AH17: =IF(AND(Dataset!G17 >5000,Dataset!H17>7000),"ACTIVE_CONSUMER","INACTIVE_CONSUMER") -> INACTIVE_CONSUMER | AM17: =IF(AND(D17>40,H17<8000,K17<300),"Eligible","Not_eligible") -> Not_eligible | AP17: =IF(AND(E17="M",F17="checking",Dataset!G17>2000,Dataset!K17>500),"good_client","bad_client") -> bad_client | AS17: Not_eligible | AT17: =IF(AND(Dataset!F17="Savings",Dataset!AS17="eligible"),"YES","NO") -> NO | AW17: yes | AX17: Good_user | BC17: =IF(H17>6000,"yes","no") -> yes
A18: 17 | B18: Amelia | C18: Allen | D18: 24 | E18: M | F18: Checking | G18: 2200 | H18: 45000 | I18: No | J18: 0 | K18: 670 | L18: Stocks | M18: standard | N18: Inactive | O18: 5 | R18: =H18/J18 -> #DIV/0! | S18: =IFERROR(R18,"DIVISION ERROR") -> DIVISION ERROR | U18: FALSE | W18: =IF(ISODD(D18),"ODD","EVEN") -> EVEN | X18: =_xlfn.RANK.AVG(K18,$K$2:$K$350,0) -> 334 | AA18: =IF(N18="Active","Good_user","Bad_user") -> Bad_user | AD18: =ISERROR(R18) -> TRUE | AF18: =ISTEXT(O18) -> FALSE | AH18: =IF(AND(Dataset!G18 >5000,Dataset!H18>7000),"ACTIVE_CONSUMER","INACTIVE_CONSUMER") -> INACTIVE_CONSUMER | AM18: =IF(AND(D18>40,H18<8000,K18<300),"Eligible","Not_eligible") -> Not_eligible | AP18: =IF(AND(E18="M",F18="checking",Dataset!G18>2000,Dataset!K18>500),"good_client","bad_client") -> good_client | AS18: Not_eligible | AT18: =IF(AND(Dataset!F18="Savings",Dataset!AS18="eligible"),"YES","NO") -> NO | AW18: yes | AX18: Bad_user | BC18: =IF(H18>6000,"yes","no") -> yes
A19: 18 | B19: Lucas | C19: Young | D19: 38 | E19: M | F19: Savings | G19: 15000 | H19: 77000 | I19: Yes | J19: 15000 | K19: 720 | L19: Bonds | M19: none | N19: Active | O19: No loan | R19: =H19/J19 -> 5.1333333 | S19: =IFERROR(R19,"DIVISION ERROR") -> 5.1333333 | U19: TRUE | W19: =IF(ISODD(D19),"ODD","EVEN") -> EVEN | X19: =_xlfn.RANK.AVG(K19,$K$2:$K$350,0) -> 60 | AA19: =IF(N19="Active","Good_user","Bad_user") -> Good_user | AD19: =ISERROR(R19) -> FALSE | AF19: =ISTEXT(O19) -> TRUE | AH19: =IF(AND(Dataset!G19 >5000,Dataset!H19>7000),"ACTIVE_CONSUMER","INACTIVE_CONSUMER") -> ACTIVE_CONSUMER | AM19: =IF(AND(D19>40,H19<8000,K19<300),"Eligible","Not_eligible") -> Not_eligible | AP19: =IF(AND(E19="M",F19="checking",Dataset!G19>2000,Dataset!K19>500),"good_client","bad_client") -> bad_client | AS19: Not_eligible | AT19: =IF(AND(Dataset!F19="Savings",Dataset!AS19="eligible"),"YES","NO") -> NO | AW19: no | AX19: Good_user | BC19: =IF(H19>6000,"yes","no") -> yes
A20: 19 | B20: Harper | C20: King | D20: 27 | E20: F | F20: Checking | G20: 4000 | H20: 50000 | I20: No | J20: 0 | K20: 680 | L20: Mutual Funds | M20: Premium | N20: Inactive | O20: 6 | R20: =H20/J20 -> #DIV/0! | S20: =IFERROR(R20,"DIVISION ERROR") -> DIVISION ERROR | U20: FALSE | W20: =IF(ISODD(D20),"ODD","EVEN") -> ODD | X20: =_xlfn.RANK.AVG(K20,$K$2:$K$350,0) -> 286 | AA20: =IF(N20="Active","Good_user","Bad_user") -> Bad_user | AD20: =ISERROR(R20) -> TRUE | AF20: =ISTEXT(O20) -> FALSE | AH20: =IF(AND(Dataset!G20 >5000,Dataset!H20>7000),"ACTIVE_CONSUMER","INACTIVE_CONSUMER") -> INACTIVE_CONSUMER | AM20: =IF(AND(D20>40,H20<8000,K20<300),"Eligible","Not_eligible") -> Not_eligible | AP20: =IF(AND(E20="M",F20="checking",Dataset!G20>2000,Dataset!K20>500),"good_client","bad_client") -> bad_client | AS20: Not_eligible | AT20: =IF(AND(Dataset!F20="Savings",Dataset!AS20="eligible"),"YES","NO") -> NO | AW20: yes | AX20: Bad_user | BC20: =IF(H20>6000,"yes","no") -> yes
A21: 20 | B21: Alexander | C21: Scott | D21: 41 | E21: M | F21: Savings | G21: 9000 | H21: 69000 | I21: Yes | J21: 12000 | K21: 700 | L21: Real Estate | M21: none | N21: Active | O21: 5 | R21: =H21/J21 -> 5.75 | S21: =IFERROR(R21,"DIVISION ERROR") -> 5.75 | U21: TRUE | W21: =IF(ISODD(D21),"ODD","EVEN") -> ODD | X21: =_xlfn.RANK.AVG(K21,$K$2:$K$350,0) -> 170 | AA21: =IF(N21="Active","Good_user","Bad_user") -> Good_user | AD21: =ISERROR(R21) -> FALSE | AF21: =ISTEXT(O21) -> FALSE | AH21: =IF(AND(Dataset!G21 >5000,Dataset!H21>7000),"ACTIVE_CONSUMER","INACTIVE_CONSUMER") -> ACTIVE_CONSUMER | AM21: =IF(AND(D21>40,H21<8000,K21<300),"Eligible","Not_eligible") -> Not_eligible | AP21: =IF(AND(E21="M",F21="checking",Dataset!G21>2000,Dataset!K21>500),"good_client","bad_client") -> bad_client | AS21: Not_eligible | AT21: =IF(AND(Dataset!F21="Savings",Dataset!AS21="eligible"),"YES","NO") -> NO | AW21: no | AX21: Good_user | BC21: =IF(H21>6000,"yes","no") -> yes
A22: 21 | B22: Sophia | C22: Green | D22: 32 | E22: F | F22: Checking | G22: 5500 | H22: 54000 | I22: No | J22: 0 | K22: 710 | L22: Stocks | M22: Premium | N22: Inactive | O22: 14 | R22: =H22/J22 -> #DIV/0! | S22: =IFERROR(R22,"DIVISION ERROR") -> DIVISION ERROR | U22: FALSE | W22: =IF(ISODD(D22),"ODD","EVEN") -> EVEN | X22: =_xlfn.RANK.AVG(K22,$K$2:$K$350,0) -> 120.5 | AA22: =IF(N22="Active","Good_user","Bad_user") -> Bad_user | AD22: =ISERROR(R22) -> TRUE | AF22: =ISTEXT(O22) -> FALSE | AH22: =IF(AND(Dataset!G22 >5000,Dataset!H22>7000),"ACTIVE_CONSUMER","INACTIVE_CONSUMER") -> ACTIVE_CONSUMER | AM22: =IF(AND(D22>40,H22<8000,K22<300),"Eligible","Not_eligible") -> Not_eligible | AP22: =IF(AND(E22="M",F22="checking",Dataset!G22>2000,Dataset!K22>500),"good_client","bad_client") -> bad_client | AS22: Not_eligible | AT22: =IF(AND(Dataset!F22="Savings",Dataset!AS22="eligible"),"YES","NO") -> NO | AW22: yes | AX22: Bad_user | BC22: =IF(H22>6000,"yes","no") -> yes
A23: 22 | B23: Henry | C23: Adams | D23: 47 | E23: M | F23: Savings | G23: 7000 | H23: 74000 | I23: Yes | J23: 10000 | K23: 690 | L23: Bonds | M23: standard | N23: Active | O23: 12 | R23: =H23/J23 -> 7.4 | S23: =IFERROR(R23,"DIVISION ERROR") -> 7.4 | U23: TRUE | W23: =IF(ISODD(D23),"ODD","EVEN") -> ODD | X23: =_xlfn.RANK.AVG(K23,$K$2:$K$350,0) -> 223.5 | AA23: =IF(N23="Active","Good_user","Bad_user") -> Good_user | AD23: =ISERROR(R23) -> FALSE | AF23: =ISTEXT(O23) -> FALSE | AH23: =IF(AND(Dataset!G23 >5000,Dataset!H23>7000),"ACTIVE_CONSUMER","INACTIVE_CONSUMER") -> ACTIVE_CONSUMER | AM23: =IF(AND(D23>40,H23<8000,K23<300),"Eligible","Not_eligible") -> Not_eligible | AP23: =IF(AND(E23="M",F23="checking",Dataset!G23>2000,Dataset!K23>500),"good_client","bad_client") -> bad_client | AS23: Not_eligible | AT23: =IF(AND(Dataset!F23="Savings",Dataset!AS23="eligible"),"YES","NO") -> NO | AW23: yes | AX23: Good_user | BC23: =IF(H23>6000,"yes","no") -> yes
A24: 23 | B24: Ella | C24: Baker | D24: 35 | E24: F | F24: Checking | G24: 6000 | H24: 68000 | I24: No | J24: 0 | K24: 720 | L24: Mutual Funds | M24: standard | N24: Inactive | O24: 11 | R24: =H24/J24 -> #DIV/0! | S24: =IFERROR(R24,"DIVISION ERROR") -> DIVISION ERROR | U24: FALSE | W24: =IF(ISODD(D24),"ODD","EVEN") -> ODD | X24: =_xlfn.RANK.AVG(K24,$K$2:$K$350,0) -> 60 | AA24: =IF(N24="Active","Good_user","Bad_user") -> Bad_user | AD24: =ISERROR(R24) -> TRUE | AF24: =ISTEXT(O24) -> FALSE | AH24: =IF(AND(Dataset!G24 >5000,Dataset!H24>7000),"ACTIVE_CONSUMER","INACTIVE_CONSUMER") -> ACTIVE_CONSUMER | AM24: =IF(AND(D24>40,H24<8000,K24<300),"Eligible","Not_eligible") -> Not_eligible | AP24: =IF(AND(E24="M",F24="checking",Dataset!G24>2000,Dataset!K24>500),"good_client","bad_client") -> bad_client | AS24: Not_eligible | AT24: =IF(AND(Dataset!F24="Savings",Dataset!AS24="eligible"),"YES","NO") -> NO | AW24: yes | AX24: Bad_user | BC24: =IF(H24>6000,"yes","no") -> yes
A25: 24 | B25: Jack | C25: Nelson | D25: 29 | E25: M | F25: Savings | G25: 2500 | H25: 45000 | I25: Yes | J25: 5000 | K25: 670 | L25: Real Estate | M25: standard | N25: Active | O25: 8 | R25: =H25/J25 -> 9 | S25: =IFERROR(R25,"DIVISION ERROR") -> 9 | U25: TRUE | W25: =IF(ISODD(D25),"ODD","EVEN") -> ODD | Y25: =_xlfn.RANK.AVG(K25,$K$2:$K$350,0) -> 334 | AB25: =IF(N25="Active","Good_user","Bad_user") -> Good_user | AE25: =ISERROR(R25) -> FALSE | AG25: =ISTEXT(O25) -> FALSE | AI25: =IF(AND(Dataset!G25 >5000,Dataset!H25>7000),"ACTIVE_CONSUMER","INACTIVE_CONSUMER") -> INACTIVE_CONSUMER | AN25: =IF(AND(D25>40,H25<8000,K25<300),"Eligible","Not_eligible") -> Not_eligible | AQ25: =IF(AND(E25="M",F25="checking",Dataset!G25>2000,Dataset!K25>500),"good_client","bad_client") -> bad_client | AT25: Not_eligible | AU25: =IF(AND(Dataset!F25="Savings",Dataset!AT25="eligible"),"YES","NO") -> NO | AX25: yes | AY25: Good_user | BD25: =IF(H25>6000,"yes","no") -> yes
A26: 25 | B26: Grace | C26: Carter | D26: 42 | E26: F | F26: Checking | G26: 11000 | H26: 80000 | I26: No | J26: 0 | K26: 740 | L26: Stocks | M26: none | N26: Inactive | O26: 4 | R26: =H26/J26 -> #DIV/0! | S26: =IFERROR(R26,"DIVISION ERROR") -> DIVISION ERROR | U26: FALSE | W26: =IF(ISODD(D26),"ODD","EVEN") -> EVEN | Y26: =_xlfn.RANK.AVG(K26,$K$2:$K$350,0) -> 13 | AB26: =IF(N26="Active","Good_user","Bad_user") -> Bad_user | AE26: =ISERROR(R26) -> TRUE | AG26: =ISTEXT(O26) -> FALSE | AI26: =IF(AND(Dataset!G26 >5000,Dataset!H26>7000),"ACTIVE_CONSUMER","INACTIVE_CONSUMER") -> ACTIVE_CONSUMER | AN26: =IF(AND(D26>40,H26<8000,K26<300),"Eligible","Not_eligible") -> Not_eligible | AQ26: =IF(AND(E26="M",F26="checking",Dataset!G26>2000,Dataset!K26>500),"good_client","bad_client") -> bad_client | AT26: Not_eligible | AU26: =IF(AND(Dataset!F26="Savings",Dataset!AT26="eligible"),"YES","NO") -> NO | AX26: no | AY26: Bad_user | BD26: =IF(H26>6000,"yes","no") -> yes
A27: 26 | B27: Michael | C27: Mitchell | D27: 50 | E27: M | F27: Savings | G27: 3000 | H27: 47000 | I27: Yes | J27: 8000 | K27: 680 | L27: Bonds | M27: none | N27: Active | O27: 13 | R27: =H27/J27 -> 5.875 | S27: =IFERROR(R27,"DIVISION ERROR") -> 5.875 | U27: TRUE | W27: =IF(ISODD(D27),"ODD","EVEN") -> EVEN | Y27: =_xlfn.RANK.AVG(K27,$K$2:$K$350,0) -> 286 | AB27: =IF(N27="Active","Good_user","Bad_user") -> Good_user | AE27: =ISERROR(R27) -> FALSE | AG27: =ISTEXT(O27) -> FALSE | AI27: =IF(AND(Dataset!G27 >5000,Dataset!H27>7000),"ACTIVE_CONSUMER","INACTIVE_CONSUMER") -> INACTIVE_CONSUMER | AN27: =IF(AND(D27>40,H27<8000,K27<300),"Eligible","Not_eligible") -> Not_eligible | AQ27: =IF(AND(E27="M",F27="checking",Dataset!G27>2000,Dataset!K27>500),"good_client","bad_client") -> bad_client | AT27: Not_eligible | AU27: =IF(AND(Dataset!F27="Savings",Dataset!AT27="eligible"),"YES","NO") -> NO | AX27: no | AY27: Good_user | BD27: =IF(H27>6000,"yes","no") -> yes
A28: 27 | B28: Lily | C28: Roberts | D28: 28 | E28: F | F28: Checking | G28: 4000 | H28: 53000 | I28: No | J28: 0 | K28: 690 | L28: Mutual Funds | M28: Premium | N28: Inactive | O28: 7 | R28: =H28/J28 -> #DIV/0! | S28: =IFERROR(R28,"DIVISION ERROR") -> DIVISION ERROR | U28: FALSE | W28: =IF(ISODD(D28),"ODD","EVEN") -> EVEN | Y28: =_xlfn.RANK.AVG(K28,$K$2:$K$350,0) -> 223.5 | AB28: =IF(N28="Active","Good_user","Bad_user") -> Bad_user | AE28: =ISERROR(R28) -> TRUE | AG28: =ISTEXT(O28) -> FALSE | AI28: =IF(AND(Dataset!G28 >5000,Dataset!H28>7000),"ACTIVE_CONSUMER","INACTIVE_CONSUMER") -> INACTIVE_CONSUMER | AN28: =IF(AND(D28>40,H28<8000,K28<300),"Eligible","Not_eligible") -> Not_eligible | AQ28: =IF(AND(E28="M",F28="checking",Dataset!G28>2000,Dataset!K28>500),"good_client","bad_client") -> bad_client | AT28: Not_eligible | AU28: =IF(AND(Dataset!F28="Savings",Dataset!AT28="eligible"),"YES","NO") -> NO | AX28: yes | AY28: Bad_user | BD28: =IF(H28>6000,"yes","no") -> yes
A29: 28 | B29: James | C29: Martinez | D29: 36 | E29: M | F29: Savings | G29: 9000 | H29: 71000 | I29: Yes | J29: 13000 | K29: 700 | L29: Real Estate | M29: standard | N29: Active | O29: 4 | R29: =H29/J29 -> 5.4615385 | S29: =IFERROR(R29,"DIVISION ERROR") -> 5.4615385 | U29: TRUE | W29: =IF(ISODD(D29),"ODD","EVEN") -> EVEN | Y29: =_xlfn.RANK.AVG(K29,$K$2:$K$350,0) -> 170 | AB29: =IF(N29="Active","Good_user","Bad_user") -> Good_user | AE29: =ISERROR(R29) -> FALSE | AG29: =ISTEXT(O29) -> FALSE | AI29: =IF(AND(Dataset!G29 >5000,Dataset!H29>7000),"ACTIVE_CONSUMER","INACTIVE_CONSUMER") -> ACTIVE_CONSUMER | AN29: =IF(AND(D29>40,H29<8000,K29<300),"Eligible","Not_eligible") -> Not_eligible | AQ29: =IF(AND(E29="M",F29="checking",Dataset!G29>2000,Dataset!K29>500),"good_client","bad_client") -> bad_client | AT29: Not_eligible | AU29: =IF(AND(Dataset!F29="Savings",Dataset!AT29="eligible"),"YES","NO") -> NO | AX29: yes | AY29: Good_user | BD29: =IF(H29>6000,"yes","no") -> yes
A30: 29 | B30: Natalie | C30: Thompson | D30: 41 | E30: F | F30: Checking | G30: 8000 | H30: 67000 | I30: No | J30: 0 | K30: 710 | L30: Stocks | M30: none | N30: Inactive | O30: 14 | R30: =H30/J30 -> #DIV/0! | S30: =IFERROR(R30,"DIVISION ERROR") -> DIVISION ERROR | U30: FALSE | W30: =IF(ISODD(D30),"ODD","EVEN") -> ODD | Y30: =_xlfn.RANK.AVG(K30,$K$2:$K$350,0) -> 120.5 | AB30: =IF(N30="Active","Good_user","Bad_user") -> Bad_user | AE30: =ISERROR(R30) -> TRUE | AG30: =ISTEXT(O30) -> FALSE | AI30: =IF(AND(Dataset!G30 >5000,Dataset!H30>7000),"ACTIVE_CONSUMER","INACTIVE_CONSUMER") -> ACTIVE_CONSUMER | AN30: =IF(AND(D30>40,H30<8000,K30<300),"Eligible","Not_eligible") -> Not_eligible | AQ30: =IF(AND(E30="M",F30="checking",Dataset!G30>2000,Dataset!K30>500),"good_client","bad_client") -> bad_client | AT30: Not_eligible | AU30: =IF(AND(Dataset!F30="Savings",Dataset!AT30="eligible"),"YES","NO") -> NO | AX30: no | AY30: Bad_user | BD30: =IF(H30>6000,"yes","no") -> yes
A31: 30 | B31: Oliver | C31: Walker | D31: 30 | E31: M | F31: Savings | G31: 5000 | H31: 55000 | I31: Yes | J31: 7000 | K31: 690 | L31: Bonds | M31: none | N31: Active | O31: 5 | R31: =H31/J31 -> 7.8571429 | S31: =IFERROR(R31,"DIVISION ERROR") -> 7.8571429 | U31: TRUE | W31: =IF(ISODD(D31),"ODD","EVEN") -> EVEN | Y31: =_xlfn.RANK.AVG(K31,$K$2:$K$350,0) -> 223.5 | AB31: =IF(N31="Active","Good_user","Bad_user") -> Good_user | AE31: =ISERROR(R31) -> FALSE | AG31: =ISTEXT(O31) -> FALSE | AI31: =IF(AND(Dataset!G31 >5000,Dataset!H31>7000),"ACTIVE_CONSUMER","INACTIVE_CONSUMER") -> INACTIVE_CONSUMER | AN31: =IF(AND(D31>40,H31<8000,K31<300),"Eligible","Not_eligible") -> Not_eligible | AQ31: =IF(AND(E31="M",F31="checking",Dataset!G31>2000,Dataset!K31>500),"good_client","bad_client") -> bad_client | AT31: Not_eligible | AU31: =IF(AND(Dataset!F31="Savings",Dataset!AT31="eligible"),"YES","NO") -> NO | AX31: no | AY31: Good_user | BD31: =IF(H31>6000,"yes","no") -> yes
A32: 31 | B32: Ava | C32: Carter | D32: 29 | E32: F | F32: Checking | G32: 3000 | H32: 48000 | I32: No | J32: 0 | K32: 670 | L32: Mutual Funds | M32: Premium | N32: Inactive | O32: 10 | R32: =H32/J32 -> #DIV/0! | S32: =IFERROR(R32,"DIVISION ERROR") -> DIVISION ERROR | U32: FALSE | W32: =IF(ISODD(D32),"ODD","EVEN") -> ODD | Y32: =_xlfn.RANK.AVG(K32,$K$2:$K$350,0) -> 334 | AB32: =IF(N32="Active","Good_user","Bad_user") -> Bad_user | AE32: =ISERROR(R32) -> TRUE | AG32: =ISTEXT(O32) -> FALSE | AI32: =IF(AND(Dataset!G32 >5000,Dataset!H32>7000),"ACTIVE_CONSUMER","INACTIVE_CONSUMER") -> INACTIVE_CONSUMER | AN32: =IF(AND(D32>40,H32<8000,K32<300),"Eligible","Not_eligible") -> Not_eligible | AQ32: =IF(AND(E32="M",F32="checking",Dataset!G32>2000,Dataset!K32>500),"good_client","bad_client") -> bad_client | AT32: Not_eligible | AU32: =IF(AND(Dataset!F32="Savings",Dataset!AT32="eligible"),"YES","NO") -> NO | AX32: yes | AY32: Bad_user | BD32: =IF(H32>6000,"yes","no") -> yes
A33: 32 | B33: Ethan | C33: Anderson | D33: 34 | E33: M | F33: Savings | G33: 11000 | H33: 62000 | I33: Yes | J33: 12000 | K33: 720 | L33: Real Estate | M33: Premium | N33: Active | O33: 10 | R33: =H33/J33 -> 5.1666667 | S33: =IFERROR(R33,"DIVISION ERROR") -> 5.1666667 | U33: TRUE | W33: =IF(ISODD(D33),"ODD","EVEN") -> EVEN | Y33: =_xlfn.RANK.AVG(K33,$K$2:$K$350,0) -> 60 | AB33: =IF(N33="Active","Good_user","Bad_user") -> Good_user | AE33: =ISERROR(R33) -> FALSE | AG33: =ISTEXT(O33) -> FALSE | AI33: =IF(AND(Dataset!G33 >5000,Dataset!H33>7000),"ACTIVE_CONSUMER","INACTIVE_CONSUMER") -> ACTIVE_CONSUMER | AN33: =IF(AND(D33>40,H33<8000,K33<300),"Eligible","Not_eligible") -> Not_eligible | AQ33: =IF(AND(E33="M",F33="checking",Dataset!G33>2000,Dataset!K33>500),"good_client","bad_client") -> bad_client | AT33: Not_eligible | AU33: =IF(AND(Dataset!F33="Savings",Dataset!AT33="eligible"),"YES","NO") -> NO | AX33: yes | AY33: Good_user | BD33: =IF(H33>6000,"yes","no") -> yes
A34: 33 | B34: Mia | C34: Nelson | D34: 37 | E34: F | F34: Checking | G34: 5500 | H34: 69000 | I34: No | J34: 0 | K34: 710 | L34: Stocks | M34: Premium | N34: Inactive | O34: 7 | R34: =H34/J34 -> #DIV/0! | S34: =IFERROR(R34,"DIVISION ERROR") -> DIVISION ERROR | U34: FALSE | W34: =IF(ISODD(D34),"ODD","EVEN") -> ODD | Y34: =_xlfn.RANK.AVG(K34,$K$2:$K$350,0) -> 120.5 | AB34: =IF(N34="Active","Good_user","Bad_user") -> Bad_user | AE34: =ISERROR(R34) -> TRUE | AG34: =ISTEXT(O34) -> FALSE | AI34: =IF(AND(Dataset!G34 >5000,Dataset!H34>7000),"ACTIVE_CONSUMER","INACTIVE_CONSUMER") -> ACTIVE_CONSUMER | AN34: =IF(AND(D34>40,H34<8000,K34<300),"Eligible","Not_eligible") -> Not_eligible | AQ34: =IF(AND(E34="M",F34="checking",Dataset!G34>2000,Dataset!K34>500),"good_client","bad_client") -> bad_client | AT34: Not_eligible | AU34: =IF(AND(Dataset!F34="Savings",Dataset!AT34="eligible"),"YES","NO") -> NO | AX34: yes | AY34: Bad_user | BD34: =IF(H34>6000,"yes","no") -> yes
A35: 34 | B35: Daniel | C35: Smith | D35: 45 | E35: M | F35: Checking | G35: 7000 | H35: 74000 | I35: Yes | J35: 15000 | K35: 680 | L35: Bonds | M35: Premium | N35: Active | O35: 5 | R35: =H35/J35 -> 4.9333333 | S35: =IFERROR(R35,"DIVISION ERROR") -> 4.9333333 | U35: TRUE | W35: =IF(ISODD(D35),"ODD","EVEN") -> ODD | Y35: =_xlfn.RANK.AVG(K35,$K$2:$K$350,0) -> 286 | AB35: =IF(N35="Active","Good_user","Bad_user") -> Good_user | AE35: =ISERROR(R35) -> FALSE | AG35: =ISTEXT(O35) -> FALSE | AI35: =IF(AND(Dataset!G35 >5000,Dataset!H35>7000),"ACTIVE_CONSUMER","INACTIVE_CONSUMER") -> ACTIVE_CONSUMER | AN35: =IF(AND(D35>40,H35<8000,K35<300),"Eligible","Not_eligible") -> Not_eligible | AQ35: =IF(AND(E35="M",F35="checking",Dataset!G35>2000,Dataset!K35>500),"good_client","bad_client") -> good_client | AT35: Not_eligible | AU35: =IF(AND(Dataset!F35="Savings",Dataset!AT35="eligible"),"YES","NO") -> NO | AX35: yes | AY35: Good_user | BD35: =IF(H35>6000,"yes","no") -> yes
A36: 35 | B36: Sophia | C36: Johnson | D36: 40 | E36: F | F36: Checking | G36: 2000 | H36: 50000 | I36: No | J36: 0 | K36: 720 | L36: Mutual Funds | M36: Premium | N36: Inactive | O36: 15 | R36: =H36/J36 -> #DIV/0! | S36: =IFERROR(R36,"DIVISION ERROR") -> DIVISION ERROR | U36: FALSE | W36: =IF(ISODD(D36),"ODD","EVEN") -> EVEN | Y36: =_xlfn.RANK.AVG(K36,$K$2:$K$350,0) -> 60 | AB36: =IF(N36="Active","Good_user","Bad_user") -> Bad_user | AE36: =ISERROR(R36) -> TRUE | AG36: =ISTEXT(O36) -> FALSE | AI36: =IF(AND(Dataset!G36 >5000,Dataset!H36>7000),"ACTIVE_CONSUMER","INACTIVE_CONSUMER") -> INACTIVE_CONSUMER | AN36: =IF(AND(D36>40,H36<8000,K36<300),"Eligible","Not_eligible") -> Not_eligible | AQ36: =IF(AND(E36="M",F36="checking",Dataset!G36>2000,Dataset!K36>500),"good_client","bad_client") -> bad_client | AT36: Not_eligible | AU36: =IF(AND(Dataset!F36="Savings",Dataset!AT36="eligible"),"YES","NO") -> NO | AX36: yes | AY36: Bad_user | BD36: =IF(H36>6000,"yes","no") -> yes
... A38: 37 | B38: Isabella | C38: Thompson | D38: 31 | E38: F | F38: Checking | G38: 3500 | H38: 62000 | I38: No | J38: 0 | K38: 680 | L38: Stocks | M38: none | N38: Inactive | O38: 15 | R38: =H38/J38 -> #DIV/0! | S38: =IFERROR(R38,"DIVISION ERROR") -> DIVISION ERROR | U38: FALSE | W38: =IF(ISODD(D38),"ODD","EVEN") -> ODD | Y38: =_xlfn.RANK.AVG(K38,$K$2:$K$350,0) -> 286 | AB38: =IF(N38="Active","Good_user","Bad_user") -> Bad_user | AE38: =ISERROR(R38) -> TRUE | AG38: =ISTEXT(O38) -> FALSE | AI38: =IF(AND(Dataset!G38 >5000,Dataset!H38>7000),"ACTIVE_CONSUMER","INACTIVE_CONSUMER") -> INACTIVE_CONSUMER | AN38: =IF(AND(D38>40,H38<8000,K38<300),"Eligible","Not_eligible") -> Not_eligible | AQ38: =IF(AND(E38="M",F38="checking",Dataset!G38>2000,Dataset!K38>500),"good_client","bad_client") -> bad_client | AT38: Not_eligible | AU38: =IF(AND(Dataset!F38="Savings",Dataset!AT38="eligible"),"YES","NO") -> NO | AX38: no | AY38: Bad_user | BD38: =IF(H38>6000,"yes","no") -> yes
A39: 38 | B39: Jacob | C39: Harris | D39: 53 | E39: M | F39: Savings | G39: 4000 | H39: 48000 | I39: Yes | J39: 5000 | K39: 710 | L39: Bonds | M39: none | N39: Active | O39: No loan | R39: =H39/J39 -> 9.6 | S39: =IFERROR(R39,"DIVISION ERROR") -> 9.6 | U39: TRUE | W39: =IF(ISODD(D39),"ODD","EVEN") -> ODD | Y39: =_xlfn.RANK.AVG(K39,$K$2:$K$350,0) -> 120.5 | AB39: =IF(N39="Active","Good_user","Bad_user") -> Good_user | AE39: =ISERROR(R39) -> FALSE | AG39: =ISTEXT(O39) -> TRUE | AI39: =IF(AND(Dataset!G39 >5000,Dataset!H39>7000),"ACTIVE_CONSUMER","INACTIVE_CONSUMER") -> INACTIVE_CONSUMER | AN39: =IF(AND(D39>40,H39<8000,K39<300),"Eligible","Not_eligible") -> Not_eligible | AQ39: =IF(AND(E39="M",F39="checking",Dataset!G39>2000,Dataset!K39>500),"good_client","bad_client") -> bad_client | AT39: Not_eligible | AU39: =IF(AND(Dataset!F39="Savings",Dataset!AT39="eligible"),"YES","NO") -> NO | AX39: no | AY39: Good_user | BD39: =IF(H39>6000,"yes","no") -> yes
A40: 39 | B40: Harper | C40: Adams | D40: 28 | E40: F | F40: Checking | G40: 5500 | H40: 59000 | I40: No | J40: 0 | K40: 700 | L40: Mutual Funds | M40: none | N40: Inactive | O40: 14 | R40: =H40/J40 -> #DIV/0! | S40: =IFERROR(R40,"DIVISION ERROR") -> DIVISION ERROR | U40: FALSE | W40: =IF(ISODD(D40),"ODD","EVEN") -> EVEN | Y40: =_xlfn.RANK.AVG(K40,$K$2:$K$350,0) -> 170 | AB40: =IF(N40="Active","Good_user","Bad_user") -> Bad_user | AE40: =ISERROR(R40) -> TRUE | AG40: =ISTEXT(O40) -> FALSE | AI40: =IF(AND(Dataset!G40 >5000,Dataset!H40>7000),"ACTIVE_CONSUMER","INACTIVE_CONSUMER") -> ACTIVE_CONSUMER | AN40: =IF(AND(D40>40,H40<8000,K40<300),"Eligible","Not_eligible") -> Not_eligible | AQ40: =IF(AND(E40="M",F40="checking",Dataset!G40>2000,Dataset!K40>500),"good_client","bad_client") -> bad_client | AT40: Not_eligible | AU40: =IF(AND(Dataset!F40="Savings",Dataset!AT40="eligible"),"YES","NO") -> NO | AX40: no | AY40: Bad_user | BD40: =IF(H40>6000,"yes","no") -> yes
A41: 40 | B41: Alexander | C41: Davis | D41: 46 | E41: M | F41: Savings | G41: 9000 | H41: 73000 | I41: Yes | J41: 13000 | K41: 720 | L41: Real Estate | M41: none | N41: Active | O41: 8 | R41: =H41/J41 -> 5.6153846 | S41: =IFERROR(R41,"DIVISION ERROR") -> 5.6153846 | U41: TRUE | W41: =IF(ISODD(D41),"ODD","EVEN") -> EVEN | Y41: =_xlfn.RANK.AVG(K41,$K$2:$K$350,0) -> 60 | AB41: =IF(N41="Active","Good_user","Bad_user") -> Good_user | AE41: =ISERROR(R41) -> FALSE | AG41: =ISTEXT(O41) -> FALSE | AI41: =IF(AND(Dataset!G41 >5000,Dataset!H41>7000),"ACTIVE_CONSUMER","INACTIVE_CONSUMER") -> ACTIVE_CONSUMER | AN41: =IF(AND(D41>40,H41<8000,K41<300),"Eligible","Not_eligible") -> Not_eligible | AQ41: =IF(AND(E41="M",F41="checking",Dataset!G41>2000,Dataset!K41>500),"good_client","bad_client") -> bad_client | AT41: Not_eligible | AU41: =IF(AND(Dataset!F41="Savings",Dataset!AT41="eligible"),"YES","NO") -> NO | AX41: no | AY41: Good_user | BD41: =IF(H41>6000,"yes","no") -> yes
...

Sheet QUESTIONS
B2: Easy Level Story Problems
B3: Average Income: As a junior manager at SwiftBank, you've been asked to help the bank understand the financial profile of its customers. Your first task is to calculate the average annual income of all account holders. Can you help SwiftBank get this important insight?
B4: Median Bank Balance: The finance team at SwiftBank is trying to understand the typical financial standing of its clients. They’ve asked you to find the median bank balance, which represents the middle value in the data. Can you calculate this to provide a better picture of the average customer’s savings?
B5: Smallest Loan: Your manager needs to identify the 5th smallest loan amount among all SwiftBank customers. This will help understand the lower end of loan distributions. Can you find the 5th smallest loan amount in the dataset?
B6: 3rd Highest Credit Score: The credit team is working on a campaign targeting customers with excellent credit scores. To begin, they need you to identify the customer with the 3rd highest credit score in the entire bank. Can you help find this high credit score?
B7: Most Frequent Credit Score: SwiftBank is trying to identify credit score patterns among its customers before issuing new loans. To assist, you’ve been asked to find the credit score that appears most frequently in the dataset. Can you determine which score is most common?
B8: Active Female Clients Over 30: SwiftBank is preparing to launch a financial product specifically targeted at women over 30 who use online banking and have a premium credit card. The marketing team needs to know how many of these clients meet the criteria. Can you provide the total number of qualifying customers?
B9: Income-to-Loan Analysis: You’re working on analyzing the income-to-loan ratio for SwiftBank’s customers. If any division error occurs, such as when there is no loan, you should label those cases as “Division Error.” Can you identify these errors and clean up the data?
B10: Check Data Types: In your income-to-loan analysis, you want to ensure that all the calculated values are numbers. If any of the results are not numeric, further investigation is needed. Can you check which values are not numbers and flag them for review?
B11: Odd and Even Age Categorization: SwiftBank wants to better understand the age distribution of its customers. To do so, they need to separate customers into two categories: odd-aged and even-aged. Can you categorize each client based on whether their age is odd or even?
B12: Lowest Account Balance (Premium Credit Card): As part of their rewards program, SwiftBank needs to identify the customer with the lowest account balance who holds a premium credit card. Can you determine who this is?
B13: Credit Score Ranking: SwiftBank is preparing to offer new high-value loans, but only to clients with excellent credit scores. To assist with this, they need you to rank all customers by credit score, from highest to lowest. Can you generate this ranking?
... B46: Smallest Loan & Stock Investors: The investment team wants to know which clients invest in stocks, use a standard credit card, and have the smallest loan. Can you identify these clients and find out the smallest loan amount?

Sheet EASY
B1: EASY
A2: Q1 | B2: Average Income: As a junior manager at SwiftBank, you've been asked to help the bank understand the financial profile of its customers. Your first task is to calculate the average annual income of all account holders. Can you help SwiftBank get this important insight?
A3: ANS-1 | B3: To calculate the average annual income of all the account holders, we can use the function average.
B4: average=AVERAGE(Dataset!H2:H350) | F4: =AVERAGE(Dataset!H2:H350) -> 60260.745
A7: Q2 | B7: Median Bank Balance: The finance team at SwiftBank is trying to understand the typical financial standing of its clients. They’ve asked you to find the median bank balance, which represents the middle value in the data. Can you calculate this to provide a better picture of the average customer’s savings?
A8: ANS-2 | B8: median=MEDIAN(Dataset!G2:G350) | F8: =MEDIAN(Dataset!G2:G350) -> 5500
A10: Q3 | B10: Smallest Loan: Your manager needs to identify the 5th smallest loan amount among all SwiftBank customers. This will help understand the lower end of loan distributions. Can you find the 5th smallest loan amount in the dataset?
A11: ANS-3 | B11: smallest=SMALL(Dataset!J2:J350,5) | G11: =SMALL(Dataset!J2:J350,5) -> 0
B12: Because there are many customers who haven't taken a loan from the bank.
A14: Q4 | B14: 3rd Highest Credit Score: The credit team is working on a campaign targeting customers with excellent credit scores. To begin, they need you to identify the customer with the 3rd highest credit score in the entire bank. Can you help find this high credit score?
A15: ANS-4 | B15: laregest=LARGE(Dataset!K2:K350,3) | F15: =LARGE(Dataset!K2:K350,3) -> 750 | G15: 0r | H15: LARGE(UNIQUE(Dataset!K2:K350),3) | L15: =LARGE(_xlfn.UNIQUE(Dataset!K2:K350),3) -> 730
A17: Q5 | B17: Most Frequent Credit Score: SwiftBank is trying to identify credit score patterns among its customers before issuing new loans. To assist, you’ve been asked to find the credit score that appears most frequently in the dataset. Can you determine which score is most common?
A18: ANS-5 | B18: Mode=MODE.SNGL(Dataset!K2:K350) | F18: =_xlfn.MODE.SNGL(Dataset!K2:K350) -> 720
A20: Q6 | B20: Active Female Clients Over 30: SwiftBank is preparing to launch a financial product specifically targeted at women over 30 who use online banking and have a premium credit card. The marketing team needs to know how many of these clients meet the criteria. Can you provide the total number of qualifying customers?
A21: ANS-6 | B21: total client's who meets this critearia are=COUNTIFS(Dataset!E2:E350,Dataset!E3,Dataset!D2:D350,">30",Dataset!N2:N350,Dataset!N2,Dataset!M2:M350,"<>none") | P21: =COUNTIFS(Dataset!D2:D350,">30",Dataset!E2:E350,"F",Dataset!M2:M350,"Premium",Dataset!N2:N350,"Active") -> 0
A23: Q7 | B23: Income-to-Loan Analysis: You’re working on analyzing the income-to-loan ratio for SwiftBank’s customers. If any division error occurs, such as when there is no loan, you should label those cases as “Division Error.” Can you identify these errors and clean up the data?
A24: ANS-7 | B24: Firstly, you need to create a new column, column P, to calculate the income-loan ratio. After that, apply the IFERROR formula to handle any errors, and label them as 'Division Error' if an error occurs.
A26: Q8 | B26: Check Data Types: In your income-to-loan analysis, you want to ensure that all the calculated values are numbers. If any of the results are not numeric, further investigation is needed. Can you check which values are not numbers and flag them for review?
A27: ANS-8 | B27: We have to use the ISNUMBER function for this problem.
A29: Q9 | B29: Odd and Even Age Categorization: SwiftBank wants to better understand the age distribution of its customers. To do so, they need to separate customers into two categories: odd-aged and even-aged. Can you categorize each client based on whether their age is odd or even?
A30: ANS-9 | B30: We have to use the ISODD function for this problem.
A32: Q10 | B32: Lowest Account Balance (Premium Credit Card): As part of their rewards program, SwiftBank needs to identify the customer with the lowest account balance who holds a premium credit card. Can you determine who this is?
A33: ANS-10 | B33: SMALL(IF(M2:M350="Premium", G2:G350), 1)
A35: Q11 | B35: Credit Score Ranking: SwiftBank is preparing to offer new high-value loans, but only to clients with excellent credit scores. To assist with this, they need you to rank all customers by credit score, from highest to lowest. Can you generate this ranking?
A36: ANS-11 | B36: We have to use the RANK function for this problem.
A38: Q12 | B38: Total Accounts and Smallest Balance: SwiftBank’s leadership team wants to know how many active accounts they have. Additionally, they need to find out which customer has the smallest account balance. Can you provide the total number of accounts and identify the customer with the lowest balance?
A39: ANS-12 | B39: Total number of accounts in the bank=COUNT(Dataset!G2:G350) | I39: =COUNT(Dataset!G2:G350) -> 349
B40: smallest account balance=SMALL(Dataset!G2:G350,1) | I40: =SMALL(Dataset!G2:G350,1) -> 1500
A42: Q13 | B42: Total Annual Income and Max Values: The bank's board of directors has requested a report that includes the total annual income of all account holders, as well as the highest annual income and largest account balance in the bank’s portfolio. Can you gather this information for the upcoming meeting?
A43: ANS-13 | B43: TOTAL ANNUAL INCOME=SUM(Dataset!H2:H350)
B44: HIGHEST ANNUAL INCOME=MAX(Dataset!H2:H350) | I44: =SUM(Dataset!H2:H350) -> 21031000
B45: LARGEST ACCOUNT BALANCE=LARGE(Dataset!G2:G350,1) | I45: =MAX(Dataset!H2:H350) -> 85000
I46: =LARGE(Dataset!G2:G350,1) -> 15000

Sheet MEDIUM
B1: MEDIUM
A2: Q1 | B2: Active Online Banking Users: SwiftBank is preparing a new strategy for its digital banking services and wants to understand how many clients actively use online banking. Additionally, they need you to calculate the 50th percentile (median) income for these active users. Can you gather this information for the bank’s report?
A3: ANS-1 | B3: Clients actively use online banking=COUNTIF(Dataset!N2:N350,Dataset!N335) | M3: =COUNTIF(Dataset!N2:N350,Dataset!N335) -> 182
B4: 50th percentile=PERCENTILE.INC(IF(Dataset!N2:N350="Active",Dataset!H2:H350),0.5) | M4: {=_xlfn.PERCENTILE.INC(IF(Dataset!N2:N350="Active",Dataset!H2:H350),0.5)} -> 60000
A6: Q2 | B6: Highest Loan Amount: The credit department at SwiftBank wants to know how many clients have taken out loans. Additionally, they need to identify the highest loan amount in the system. Can you find this information?
A7: ANS-2 | B7: clients who have taken loan=COUNTIF(Dataset!I2:I350,Dataset!I335) | M7: =COUNTIF(Dataset!I2:I350,Dataset!I335) -> 169
B8: the highest loan amount in the system=MAX(Dataset!J2:J350) | M8: =MAX(Dataset!J2:J350) -> 20000
A10: Q3 | B10: Non-Borrowers’ Smallest Balance: The bank’s savings team is conducting a study on customers who haven’t taken out any loans. As part of this, they need you to find the 3rd smallest account balance among these non-borrowers. Can you provide the data?
A11: ANS-3 | B11: the 3rd smallest account balance among non-borrowers=SMALL(UNIQUE(IF(Dataset!I2:I350="no",Dataset!G2:G350)),3) | M11: {=SMALL(_xlfn.UNIQUE(IF(Dataset!I2:I350="no",Dataset!G2:G350)),3)} -> 2200
A13: Q4 | B13: Premium Members’ Largest Balances: SwiftBank is offering exclusive rewards to clients with premium memberships and high account balances. Your task is to find the 4th largest account balance among customers who hold premium memberships. Can you help identify this group?
A14: ANS-4 | B14: the 4th largest account balance among customers who hold premium memberships.=LARGE(IF(Dataset!M2:M350="Premium",Dataset!G2:G350),4)
A16: Q5 | B16: Female Clients’ Income: SwiftBank is analyzing the financial health of its female clients. Your task is to find the second-lowest annual income among all women with accounts at the bank. Can you find this information for the analysis?
A17: ANS=5 | B17: the second-lowest annual income among all women with accounts at the banK=SMALL(IF(Dataset!E2:E350="F",Dataset!H2:H350),2) | O17: {=SMALL(_xlfn.UNIQUE(IF(Dataset!E2:E350="F",Dataset!H2:H350)),2)} -> 47000
A19: Q6 | B19: Most Common Account Balance: The finance team wants to understand the common financial behaviors of clients. To assist, they’ve asked you to identify the most common account balance among all customers. Additionally, they need the average balance. Can you determine both?
A20: ANS=6 | B20: the most common account balance among all customers=MODE.MULT(Dataset!G2:G350) | L20: {=_xlfn.MODE.MULT(Dataset!G2:G350)} -> 4000
B21: average balance =AVERAGE(Dataset!G2:G350) | L21: =AVERAGE(Dataset!G2:G350) -> 6148.9971
A23: Q7 | B23: 75th Percentile Income and Balance: SwiftBank is working on offering high-end financial products and needs to identify the wealthier clients. Your task is to find the 75th percentile for both annual income and account balance. Can you provide this data?
A24: ANS=7 | B24: the 75th percentile for annual income =PERCENTILE.INC(Dataset!H2:H350,0.75) | K24: =_xlfn.PERCENTILE.INC(Dataset!H2:H350,0.75) -> 70000
B25: the 75th percentile for Account balance =PERCENTILE.INC(G2:G350,0.75) | K25: =_xlfn.PERCENTILE.INC(Dataset!G2:G350,0.75) -> 8000
A27: Q8 | B27: Online Banking Users Categorization: To better understand digital engagement, SwiftBank is categorizing clients who use online banking as “Good” users and those who don’t as “Bad” users. Can you group the customers accordingly?
A28: ANS-8 | B28: categorizing clients who use online banking as “Good” users and those who don’t as “Bad” users=IF(Dataset!N2="Active","good","bed")
A30: Q9 | B30: Error Check in Division Calculations: In a previous analysis, you flagged cases where dividing income by loan amount resulted in errors. Now, you need to verify those flagged values using the ISERROR function to ensure there are no further issues. Can you check the accuracy of the data?
A31: ANS-9 | B31: solution=ISERROR(Dataset!Q2)
A33: Q10 | B33: Check Text in 'Interest Rate' Column: The finance department is concerned that there might be non-numeric text in the 'Interest Rate' column, which should contain only numbers. Can you use a function to check for any text entries and flag them?
A34: ANS-10 | B34: text entries=ISTEXT(Dataset!O2)
A36: Q11 | B36: 40th Percentile for Odd-Aged Clients: SwiftBank wants to learn more about clients with odd ages. First, calculate the total annual income for these odd-aged customers. Then, determine the 40th percentile of this income distribution. Can you perform this analysis?
A37: ANS=11 | B37: the total annual income for these odd-aged customer=SUMIF(Dataset!S2:S350,Dataset!S3,Dataset!H2:H350) | M37: =SUMIF(Dataset!S2:S350,Dataset!S3,Dataset!H2:H350) -> 248000
A39: Q12 | B39: Active Consumers: SwiftBank is identifying high-value clients for a new engagement program. To qualify, clients must have an account balance over $5,000 and an annual income greater than $7,000. Label these clients as “Active Consumers.” Can you complete this classification?
A40: ANS-12 | B40: clients must have an account balance over $5,000 and an annual income greater than $7,000 =IF(AND(Dataset!G2 >5000,Dataset!H2>7000),"ACTIVE_CONSUMER","INACTIVE_CONSUMER")
A42: Q13 | B42: Real Estate Investors: The investment team at SwiftBank is tracking clients who are investing in real estate. They need to know how many clients are involved, the total amount invested, and the highest individual investment in real estate. Can you prepare this investment report?
A43: AN S=13 | B43: Total client invested in real estate=COUNTIF(Dataset!L2:L350,Dataset!L339) | L43: =COUNTIF(Dataset!L2:L350,Dataset!L339) -> 86
B44: Total amount invested in real estate=SUMIF(Dataset!L2:L350,Dataset!L339,Dataset!G2:G350) | L44: =SUMIF(Dataset!L2:L350,Dataset!L339,Dataset!G2:G350) -> 613500
B45: The highest individual investment in real estate=MAXIFS(Dataset!G2:G350,Dataset!L2:L350,Dataset!L331) | L45: =_xlfn.MAXIFS(Dataset!G2:G350,Dataset!L2:L350,Dataset!L331) -> 15000

Sheet HARD
B1: HARD
A2: Q1 | B2: Female Mutual Fund Investors: The investment team wants to focus on female clients who have invested in mutual funds and have a credit score above 500. Additionally, they want to know the highest account balance among these clients. Can you provide this report?
A3: ANS-1 | B3: female clients who have invested in mutual funds and have a credit score above 500 =MAXIFS(Dataset!G2:G350,Dataset!E2:E350,Dataset!E330,Dataset!L2:L350,Dataset!L334,Dataset!K2:K350,">500") | U3: =_xlfn.MAXIFS(Dataset!G2:G350,Dataset!E2:E350,Dataset!E330,Dataset!L2:L350,Dataset!L334,Dataset!K2:K350,">500") -> 15000
A5: Q2 | B5: Not Eligible for Credit Cards: SwiftBank is reviewing its credit card offers. Clients over 40 with a credit score below 300 and an annual income under $8,000 will not be eligible for new credit cards. Can you mark these clients as “Not Eligible”?
A6: ANS-2 | B6: Clients over 40 with a credit score below 300 and an annual income under $8,000 will not be eligible for new credit cards=IF(AND(Dataset!D3>=40,Dataset!K2<300,Dataset!H2<8000),"NOT ELIGIBLE","ELIGIBLE")
A8: Q3 | B8: Inactive Female Clients’ Minimum Balance: The marketing team is preparing a new campaign targeting inactive online banking users. They need you to find the minimum account balance for female clients who are not using online banking. Additionally, they need to know how many female clients are active versus inactive in online banking. Can you provide this information?
A9: ANS-3 | B9: the minimum account balance for female clients who are not using online banking=MINIFS(Dataset!G2:G350,Dataset!E2:E350,"F",Dataset!N2:N350,"Inactive") | S9: =_xlfn.MINIFS(Dataset!G2:G350,Dataset!E2:E350,"F",Dataset!N2:N350,"Inactive") -> 1500
B10: female clients are active versus inactive in online banking=COUNTIF(Dataset!N2:N350,Dataset!N337) | S10: =COUNTIF(Dataset!N2:N350,Dataset!N337) -> 182
A12: Q4 | B12: Categorize Good and Bad Male Clients: SwiftBank is analyzing its male clients who have checking accounts. Those with a balance over $2,000 and a credit score over 500 will be classified as “Good,” while others will be classified as “Bad.” Can you complete this segmentation?
A13: ANS-4 | B13: Those with a balance over $2,000 and a credit score over 500 will be classified as “Good,” while others will be classified as “Bad.”=IF(AND(Dataset!F2=Dataset!F2,Dataset!K2>500,Dataset!G2>2000),"GOOD","BAD")
A15: Q5 | B15: Report on the Highest Income (Savings Account): SwiftBank’s leadership team needs a report on the client with the highest income who has a savings account and is eligible for a credit card. Can you prepare this report
A16: ANS-5 | B16: Create a column to determine credit card eligibility, similar to what you did in Q2, and then use the MAXIFS function. | N16: =_xlfn.MAXIFS(Dataset!G2:G350,Dataset!AT2:AT350,"eligible") -> 0
B17: The highest income is 0 because there is no consumer who satisfy the given conditions.
A19: Q6 | B19: Clients Who Accept All Offers: In the market, only a few clients accept every offer SwiftBank provides. The bank needs you to create a new column that marks clients as “In Progress” if they have accepted a credit card offer, made an investment, and are active in online banking. Can you create this column?
A20: ANS-6 | B20: marks clients as “In Progress” if they have accepted a credit card offer, made an investment, and are active in online banking.=IF(AND(T2="accepted",U2="accepted",Dataset!N2="active"),"in progress","notinprogress")
A22: Q7 | B22: Second Smallest Income (Consumers from Above Question): Using the "In Progress" customers from the previous question, the finance team would like to identify the second smallest annual income among these clients. Can you find this?
A23: ANS-7 | B23: SMALL(IF(V2:V349="IN PROGRESS",H2:H81),2)
A25: Q8 | B25: 20th Percentile for Mutual Fund Investors: Mutual fund investments are becoming increasingly popular. SwiftBank wants to calculate the 20th percentile of annual income among clients who have invested in mutual funds. Can you provide this analysis?
A26: ANS-8 | B26: the 20th percentile of annual income among clients who have invested in mutual funds.=PERCENTILE.INC(IF(Dataset!L2:L350="Mutual Funds",Dataset!G2:G350),0.2) | R26: {=_xlfn.PERCENTILE.INC(IF(Dataset!L2:L350="Mutual Funds",Dataset!G2:G350),0.2)} -> 2600
A28: Q9 | B28: Highest Balance for Each Investment Type: The investment team is studying current trends across various investment types. Your task is to find the highest account balance for each type of investment (stocks, bonds, real estate, and mutual funds). Can you gather these insights?
A29: ANS-9 | B29: the highest account balance for each type of investment stocks=MAXIFS(Dataset!H2:H350,Dataset!L2:L350,Dataset!L2) | O29: =_xlfn.MAXIFS(Dataset!H2:H350,Dataset!L2:L350,Dataset!L2) -> 80000
B30: the highest account balance for each type of investment BONDS=MAXIFS(Dataset!H2:H350,Dataset!L2:L350,Dataset!L3) | O30: =_xlfn.MAXIFS(Dataset!H2:H350,Dataset!L2:L350,Dataset!L3) -> 77000
B31: the highest account balance for each type of investment real estate=MAXIFS(Dataset!H2:H350,Dataset!L2:L350,Dataset!L5) | O31: =_xlfn.MAXIFS(Dataset!H2:H350,Dataset!L2:L350,Dataset!L5) -> 74000
B32: the highest account balance for each type of investment mutual funds=MAXIFS(Dataset!H2:H350,Dataset!L2:L350,Dataset!L4) | O32: =_xlfn.MAXIFS(Dataset!H2:H350,Dataset!L2:L350,Dataset!L4) -> 85000
A34: Q10 | B34: Credit Card Offer Income Analysis: SwiftBank wants to analyze its credit card offers based on annual income. Your task is to find the highest annual income for clients using each type of credit card (premium, standard, or none). Also, how many clients haven’t accepted any credit card offers? Can you provide this breakdown?
A35: ANS-10 | B35: The highest annual income for clients using each type of credit card premium=MAXIFS(Dataset!H2:H350,Dataset!M2:M350,Dataset!M2) | O35: =_xlfn.MAXIFS(Dataset!H2:H350,Dataset!M2:M350,Dataset!M2) -> 82000
