Workbook

Sheet Dataset
A1: Customer ID | B1: First Name | C1: Last Name | D1: Age | E1: Gender | F1: Account Type | G1: Account Balance$ | H1: Annual Income$ | I1: Loan Status | J1: Loan Amount | K1: Credit Score | L1: Investment Type | M1: Credit Card | N1: Online Banking Status | O1: Interest rate
A2: 1 | B2: John | C2: Doe | D2: 24 | E2: M | F2: Checking | G2: 2500 | H2: 55000 | I2: No | J2: 0 | K2: 720 | L2: Stocks | M2: Premium | N2: Active | O2: 7
A3: 2 | B3: Jane | C3: Smith | D3: 29 | E3: F | F3: Savings | G3: 8000 | H3: 62000 | I3: Yes | J3: 15000 | K3: 680 | L3: Bonds | M3: standard | N3: Inactive | O3: 5
A4: 3 | B4: Emily | C4: Johnson | D4: 45 | E4: F | F4: Checking | G4: 12000 | H4: 75000 | I4: No | J4: 0 | K4: 750 | L4: Mutual Funds | M4: none | N4: Active | O4: 3
A5: 4 | B5: Michael | C5: Brown | D5: 52 | E5: M | F5: Savings | G5: 3000 | H5: 48000 | I5: Yes | J5: 5000 | K5: 690 | L5: Real Estate | M5: Premium | N5: Active | O5: 3
A6: 5 | B6: Sarah | C6: Davis | D6: 37 | E6: F | F6: Checking | G6: 5000 | H6: 58000 | I6: No | J6: 0 | K6: 710 | L6: Stocks | M6: Premium | N6: Inactive | O6: 4
A7: 6 | B7: William | C7: Martinez | D7: 30 | E7: M | F7: Savings | G7: 6000 | H7: 70000 | I7: Yes | J7: 20000 | K7: 700 | L7: Bonds | M7: Premium | N7: Active | O7: 3
A8: 7 | B8: Olivia | C8: Lee | D8: 40 | E8: F | F8: Checking | G8: 15000 | H8: 82000 | I8: No | J8: 0 | K8: 730 | L8: Mutual Funds | M8: Premium | N8: Inactive | O8: 7
A9: 8 | B9: James | C9: Wilson | D9: 25 | E9: M | F9: Savings | G9: 2000 | H9: 43000 | I9: No | J9: 0 | K9: 670 | L9: Real Estate | M9: standard | N9: Active | O9: 12
A10: 9 | B10: Ava | C10: Anderson | D10: 31 | E10: F | F10: Checking | G10: 7000 | H10: 55000 | I10: Yes | J10: 10000 | K10: 720 | L10: Stocks | M10: standard | N10: Active | O10: 11
A11: 10 | B11: Ethan | C11: Thomas | D11: 44 | E11: M | F11: Savings | G11: 11000 | H11: 65000 | I11: No | J11: 0 | K11: 740 | L11: Bonds | M11: none | N11: Inactive | O11: 3
A12: 11 | B12: Isabella | C12: White | D12: 28 | E12: F | F12: Checking | G12: 4500 | H12: 47000 | I12: No | J12: 0 | K12: 690 | L12: Mutual Funds | M12: Premium | N12: Active | O12: 3
A13: 12 | B13: Benjamin | C13: Harris | D13: 39 | E13: M | F13: Savings | G13: 10000 | H13: 72000 | I13: Yes | J13: 12000 | K13: 700 | L13: Real Estate | M13: none | N13: Active | O13: No loan
A14: 13 | B14: Mia | C14: Clark | D14: 26 | E14: F | F14: Checking | G14: 3500 | H14: 53000 | I14: No | J14: 0 | K14: 680 | L14: Stocks | M14: standard | N14: Inactive | O14: 11
A15: 14 | B15: Jacob | C15: Lewis | D15: 33 | E15: M | F15: Savings | G15: 8000 | H15: 60000 | I15: Yes | J15: 8000 | K15: 710 | L15: Bonds | M15: Premium | N15: Active | O15: 11
A16: 15 | B16: Charlotte | C16: Walker | D16: 46 | E16: F | F16: Checking | G16: 13000 | H16: 85000 | I16: No | J16: 0 | K16: 740 | L16: Mutual Funds | M16: none | N16: Inactive | O16: 6
A17: 16 | B17: Daniel | C17: Hall | D17: 52 | E17: M | F17: Savings | G17: 4000 | H17: 49000 | I17: Yes | J17: 7000 | K17: 690 | L17: Real Estate | M17: Premium | N17: Active | O17: 6
A18: 17 | B18: Amelia | C18: Allen | D18: 24 | E18: M | F18: Checking | G18: 2200 | H18: 45000 | I18: No | J18: 0 | K18: 670 | L18: Stocks | M18: standard | N18: Inactive | O18: 5
A19: 18 | B19: Lucas | C19: Young | D19: 38 | E19: M | F19: Savings | G19: 15000 | H19: 77000 | I19: Yes | J19: 15000 | K19: 720 | L19: Bonds | M19: none | N19: Active | O19: No loan
A20: 19 | B20: Harper | C20: King | D20: 27 | E20: F | F20: Checking | G20: 4000 | H20: 50000 | I20: No | J20: 0 | K20: 680 | L20: Mutual Funds | M20: Premium | N20: Inactive | O20: 6
A21: 20 | B21: Alexander | C21: Scott | D21: 41 | E21: M | F21: Savings | G21: 9000 | H21: 69000 | I21: Yes | J21: 12000 | K21: 700 | L21: Real Estate | M21: none | N21: Active | O21: 5
A22: 21 | B22: Sophia | C22: Green | D22: 32 | E22: F | F22: Checking | G22: 5500 | H22: 54000 | I22: No | J22: 0 | K22: 710 | L22: Stocks | M22: Premium | N22: Inactive | O22: 14
A23: 22 | B23: Henry | C23: Adams | D23: 47 | E23: M | F23: Savings | G23: 7000 | H23: 74000 | I23: Yes | J23: 10000 | K23: 690 | L23: Bonds | M23: standard | N23: Active | O23: 12
A24: 23 | B24: Ella | C24: Baker | D24: 35 | E24: F | F24: Checking | G24: 6000 | H24: 68000 | I24: No | J24: 0 | K24: 720 | L24: Mutual Funds | M24: standard | N24: Inactive | O24: 11
A25: 24 | B25: Jack | C25: Nelson | D25: 29 | E25: M | F25: Savings | G25: 2500 | H25: 45000 | I25: Yes | J25: 5000 | K25: 670 | L25: Real Estate | M25: standard | N25: Active | O25: 8
A26: 25 | B26: Grace | C26: Carter | D26: 42 | E26: F | F26: Checking | G26: 11000 | H26: 80000 | I26: No | J26: 0 | K26: 740 | L26: Stocks | M26: none | N26: Inactive | O26: 4
A27: 26 | B27: Michael | C27: Mitchell | D27: 50 | E27: M | F27: Savings | G27: 3000 | H27: 47000 | I27: Yes | J27: 8000 | K27: 680 | L27: Bonds | M27: none | N27: Active | O27: 13
A28: 27 | B28: Lily | C28: Roberts | D28: 28 | E28: F | F28: Checking | G28: 4000 | H28: 53000 | I28: No | J28: 0 | K28: 690 | L28: Mutual Funds | M28: Premium | N28: Inactive | O28: 7
A29: 28 | B29: James | C29: Martinez | D29: 36 | E29: M | F29: Savings | G29: 9000 | H29: 71000 | I29: Yes | J29: 13000 | K29: 700 | L29: Real Estate | M29: standard | N29: Active | O29: 4
A30: 29 | B30: Natalie | C30: Thompson | D30: 41 | E30: F | F30: Checking | G30: 8000 | H30: 67000 | I30: No | J30: 0 | K30: 710 | L30: Stocks | M30: none | N30: Inactive | O30: 14
A31: 30 | B31: Oliver | C31: Walker | D31: 30 | E31: M | F31: Savings | G31: 5000 | H31: 55000 | I31: Yes | J31: 7000 | K31: 690 | L31: Bonds | M31: none | N31: Active | O31: 5
... A38: 37 | B38: Isabella | C38: Thompson | D38: 31 | E38: F | F38: Checking | G38: 3500 | H38: 62000 | I38: No | J38: 0 | K38: 680 | L38: Stocks | M38: none | N38: Inactive | O38: 15
A39: 38 | B39: Jacob | C39: Harris | D39: 53 | E39: M | F39: Savings | G39: 4000 | H39: 48000 | I39: Yes | J39: 5000 | K39: 710 | L39: Bonds | M39: none | N39: Active | O39: No loan
A40: 39 | B40: Harper | C40: Adams | D40: 28 | E40: F | F40: Checking | G40: 5500 | H40: 59000 | I40: No | J40: 0 | K40: 700 | L40: Mutual Funds | M40: none | N40: Inactive | O40: 14
A41: 40 | B41: Alexander | C41: Davis | D41: 46 | E41: M | F41: Savings | G41: 9000 | H41: 73000 | I41: Yes | J41: 13000 | K41: 720 | L41: Real Estate | M41: none | N41: Active | O41: 8
A42: 41 | B42: Ella | C42: Walker | D42: 39 | E42: F | F42: Checking | G42: 4000 | H42: 65000 | I42: No | J42: 0 | K42: 680 | L42: Stocks | M42: none | N42: Inactive | O42: 15
A43: 42 | B43: Lucas | C43: Martinez | D43: 27 | E43: M | F43: Savings | G43: 8000 | H43: 60000 | I43: Yes | J43: 8000 | K43: 710 | L43: Bonds | M43: none | N43: Active | O43: 9
A44: 43 | B44: Grace | C44: Carter | D44: 34 | E44: F | F44: Checking | G44: 2500 | H44: 53000 | I44: No | J44: 0 | K44: 690 | L44: Mutual Funds | M44: standard | N44: Inactive | O44: 4
A45: 44 | B45: James | C45: Roberts | D45: 32 | E45: M | F45: Savings | G45: 12000 | H45: 68000 | I45: Yes | J45: 15000 | K45: 720 | L45: Real Estate | M45: standard | N45: Active | O45: No loan
A46: 45 | B46: Natalie | C46: Lewis | D46: 49 | E46: F | F46: Checking | G46: 7000 | H46: 71000 | I46: No | J46: 0 | K46: 680 | L46: Stocks | M46: standard | N46: Inactive | O46: 5
...

Sheet QUESTIONS
B2: Easy Level Story Problems
B3: Average Income: As a junior manager at SwiftBank, you've been asked to help the bank understand the financial profile of its customers. Your first task is to calculate the average annual income of all account holders. Can you help SwiftBank get this important insight?
B4: Median Bank Balance: The finance team at SwiftBank is trying to understand the typical financial standing of its clients. They’ve asked you to find the median bank balance, which represents the middle value in the data. Can you calculate this to provide a better picture of the average customer’s savings?
B5: Total Accounts and Smallest Balance: SwiftBank’s leadership team wants to know how many active accounts they have. Additionally, they need to find out which customer has the smallest account balance. Can you provide the total number of accounts and identify the customer with the lowest balance?
B6: Total Annual Income and Max Values: The bank's board of directors has requested a report that includes the total annual income of all account holders, as well as the highest annual income and largest account balance in the bank’s portfolio. Can you gather this information for the upcoming meeting?
B7: Most Frequent Credit Score: SwiftBank is trying to identify credit score patterns among its customers before issuing new loans. To assist, you’ve been asked to find the credit score that appears most frequently in the dataset. Can you determine which score is most common?
B8: Lowest Account Balance (Premium Credit Card): As part of their rewards program, SwiftBank needs to identify the customer with the lowest account balance who holds a premium credit card. Can you determine who this is?
B9: You are working on analyzing the income-to-loan ratio for SwiftBank’s customers. Your task is to create a new column, Column P, to calculate the income-to-loan ratio. After that, you need to apply the following functions to that column: ISERROR, IFERROR, ISODD, ISEVEN, and ISNUMBER, ISTEXT
B11: Medium Level Story Problems
B12: Active Online Banking Users: SwiftBank is preparing a new strategy for its digital banking services and wants to understand how many clients actively use online banking. Additionally, they need you to calculate the 50th percentile (median) income for these active users. Can you gather this information for the bank’s report?
B13: Highest Loan Amount: The credit department at SwiftBank wants to know how many clients have taken out loans. Additionally, they need to identify the highest loan amount in the system. Can you find this information?
B14: Non-Borrowers’ Smallest Balance: The bank’s savings team is conducting a study on customers who haven’t taken out any loans. As part of this, they need you to find the 3rd smallest account balance among these non-borrowers. Can you provide the data?
... B27: Total Income and Largest Balance for Savings Account Holders: The bank is preparing a report on savings account holders. Your task is to calculate the total annual income for these clients and identify the largest account balance in this category. Can you help?

Sheet EASY
B1: EASY
A2: Q1 | B2: Average Income: As a junior manager at SwiftBank, you've been asked to help the bank understand the financial profile of its customers. Your first task is to calculate the average annual income of all account holders. Can you help SwiftBank get this important insight?
A3: ANS-1 | B3: To calculate the average annual income of all the account holders, we can use the function average.
B4: average=AVERAGE(Dataset!H2:H350) | F4: =AVERAGE(Dataset!H2:H350) -> 60260.745
A7: Q2 | B7: Median Bank Balance: The finance team at SwiftBank is trying to understand the typical financial standing of its clients. They’ve asked you to find the median bank balance, which represents the middle value in the data. Can you calculate this to provide a better picture of the average customer’s savings?
A8: ANS-2 | B8: median=MEDIAN(Dataset!G2:G350) | F8: =MEDIAN(Dataset!G2:G350) -> 5500
A10: Q3 | B10: Total Accounts and Smallest Balance: SwiftBank’s leadership team wants to know how many active accounts they have. Additionally, they need to find out which customer has the smallest account balance. Can you provide the total number of accounts and identify the customer with the lowest balance?
A11: ANS-3 | B11: Total number of accounts in the bank=COUNT(Dataset!G2:G350) | I11: =COUNT(Dataset!G2:G350) -> 349
B12: smallest account balance=SMALL(Dataset!G2:G350,1) | I12: =SMALL(Dataset!G2:G350,1) -> 1500
A14: Q4 | B14: Total Annual Income and Max Values: The bank's board of directors has requested a report that includes the total annual income of all account holders, as well as the highest annual income and largest account balance in the bank’s portfolio. Can you gather this information for the upcoming meeting?
A15: ANS-4 | B15: TOTAL ANNUAL INCOME=SUM(Dataset!H2:H350) | I15: =SUM(Dataset!H2:H350) -> 21031000
B16: HIGHEST ANNUAL INCOME=MAX(Dataset!H2:H350) | I16: =MAX(Dataset!H2:H350) -> 85000
B17: LARGEST ACCOUNT BALANCE=LARGE(Dataset!G2:G350,1) | I17: =LARGE(Dataset!G2:G350,1) -> 15000
A20: Q5 | B20: Most Frequent Credit Score: SwiftBank is trying to identify credit score patterns among its customers before issuing new loans. To assist, you’ve been asked to find the credit score that appears most frequently in the dataset. Can you determine which score is most common?
A21: ANS-5 | B21: Mode=MODE.SNGL(Dataset!K2:K350) | F21: =_xlfn.MODE.SNGL(Dataset!K2:K350) -> 720
A23: Q6 | B23: Lowest Account Balance (Premium Credit Card): As part of their rewards program, SwiftBank needs to identify the customer with the lowest account balance who holds a premium credit card. Can you determine who this is?
A24: ANS-6 | B24: SMALL(IF(Dataset!M2:M350=Dataset!M6,Dataset!G2:G350),1) | H24: {=SMALL(IF(Dataset!M2:M350=Dataset!M6,Dataset!G2:G350),1)} -> 1500
A26: Q7 | B26: You are working on analyzing the income-to-loan ratio for SwiftBank’s customers. Your task is to create a new column, Column P, to calculate the income-to-loan ratio. After that, you need to apply the following functions to that column: ISERROR, IFERROR, ISODD, ISEVEN, and ISNUMBER, ISTEXT
B27: Income | C27: loan | D27: Column p | F27: Iserror | G27: iferror | H27: isodd | I27: iseven | J27: isnumber | K27: istext
A28: ANS-7 | B28: 55000 | C28: 0 | D28: =B28/C28 -> #DIV/0! | F28: =ISERROR(D28) -> TRUE | G28: =IFERROR(D28,"error") -> error | H28: =ISODD(D28) -> #DIV/0! | I28: =ISEVEN(D28) -> #DIV/0! | J28: =ISNUMBER(D28) -> FALSE | K28: =ISTEXT(D28) -> FALSE
B29: 62000 | C29: 15000 | D29: =B29/C29 -> 4.1333333 | F29: =ISERROR(D29) -> FALSE | G29: =IFERROR(D29,"error") -> 4.1333333 | H29: =ISODD(D29) -> FALSE | I29: =ISEVEN(D29) -> TRUE | J29: =ISNUMBER(D29) -> TRUE | K29: =ISTEXT(D29) -> FALSE
B30: 75000 | C30: 0 | D30: =B30/C30 -> #DIV/0! | F30: =ISERROR(D30) -> TRUE | G30: =IFERROR(D30,"error") -> error | H30: =ISODD(D30) -> #DIV/0! | I30: =ISEVEN(D30) -> #DIV/0! | J30: =ISNUMBER(D30) -> FALSE | K30: =ISTEXT(D30) -> FALSE
B31: 48000 | C31: 5000 | D31: =B31/C31 -> 9.6 | F31: =ISERROR(D31) -> FALSE | G31: =IFERROR(D31,"error") -> 9.6 | H31: =ISODD(D31) -> TRUE | I31: =ISEVEN(D31) -> FALSE | J31: =ISNUMBER(D31) -> TRUE | K31: =ISTEXT(D31) -> FALSE
B32: 58000 | C32: 0 | D32: =B32/C32 -> #DIV/0! | F32: =ISERROR(D32) -> TRUE | G32: =IFERROR(D32,"error") -> error | H32: =ISODD(D32) -> #DIV/0! | I32: =ISEVEN(D32) -> #DIV/0! | J32: =ISNUMBER(D32) -> FALSE | K32: =ISTEXT(D32) -> FALSE
B33: 70000 | C33: 20000 | D33: =B33/C33 -> 3.5 | F33: =ISERROR(D33) -> FALSE | G33: =IFERROR(D33,"error") -> 3.5 | H33: =ISODD(D33) -> TRUE | I33: =ISEVEN(D33) -> FALSE | J33: =ISNUMBER(D33) -> TRUE | K33: =ISTEXT(D33) -> FALSE
B34: 82000 | C34: 0 | D34: =B34/C34 -> #DIV/0! | F34: =ISERROR(D34) -> TRUE | G34: =IFERROR(D34,"error") -> error | H34: =ISODD(D34) -> #DIV/0! | I34: =ISEVEN(D34) -> #DIV/0! | J34: =ISNUMBER(D34) -> FALSE | K34: =ISTEXT(D34) -> FALSE
B35: 43000 | C35: 0 | D35: =B35/C35 -> #DIV/0! | F35: =ISERROR(D35) -> TRUE | G35: =IFERROR(D35,"error") -> error | H35: =ISODD(D35) -> #DIV/0! | I35: =ISEVEN(D35) -> #DIV/0! | J35: =ISNUMBER(D35) -> FALSE | K35: =ISTEXT(D35) -> FALSE
B36: 55000 | C36: 10000 | D36: =B36/C36 -> 5.5 | F36: =ISERROR(D36) -> FALSE | G36: =IFERROR(D36,"error") -> 5.5 | H36: =ISODD(D36) -> TRUE | I36: =ISEVEN(D36) -> FALSE | J36: =ISNUMBER(D36) -> TRUE | K36: =ISTEXT(D36) -> FALSE
B37: 65000 | C37: 0 | D37: =B37/C37 -> #DIV/0! | F37: =ISERROR(D37) -> TRUE | G37: =IFERROR(D37,"error") -> error | H37: =ISODD(D37) -> #DIV/0! | I37: =ISEVEN(D37) -> #DIV/0! | J37: =ISNUMBER(D37) -> FALSE | K37: =ISTEXT(D37) -> FALSE
B38: 47000 | C38: 0 | D38: =B38/C38 -> #DIV/0! | F38: =ISERROR(D38) -> TRUE | G38: =IFERROR(D38,"error") -> error | H38: =ISODD(D38) -> #DIV/0! | I38: =ISEVEN(D38) -> #DIV/0! | J38: =ISNUMBER(D38) -> FALSE | K38: =ISTEXT(D38) -> FALSE
B39: 72000 | C39: 12000 | D39: =B39/C39 -> 6 | F39: =ISERROR(D39) -> FALSE | G39: =IFERROR(D39,"error") -> 6 | H39: =ISODD(D39) -> FALSE | I39: =ISEVEN(D39) -> TRUE | J39: =ISNUMBER(D39) -> TRUE | K39: =ISTEXT(D39) -> FALSE
B40: 53000 | C40: 0 | D40: =B40/C40 -> #DIV/0! | F40: =ISERROR(D40) -> TRUE | G40: =IFERROR(D40,"error") -> error | H40: =ISODD(D40) -> #DIV/0! | I40: =ISEVEN(D40) -> #DIV/0! | J40: =ISNUMBER(D40) -> FALSE | K40: =ISTEXT(D40) -> FALSE
... B376: 45000 | C376: 0 | D376: =B376/C376 -> #DIV/0! | F376: =ISERROR(D376) -> TRUE | G376: =IFERROR(D376,"error") -> error | H376: =ISODD(D376) -> #DIV/0! | I376: =ISEVEN(D376) -> #DIV/0! | J376: =ISNUMBER(D376) -> FALSE | K376: =ISTEXT(D376) -> FALSE

Sheet MEDIUM
B1: MEDIUM
A2: Q1 | B2: Active Online Banking Users: SwiftBank is preparing a new strategy for its digital banking services and wants to understand how many clients actively use online banking. Additionally, they need you to calculate the 50th percentile (median) income for these active users. Can you gather this information for the bank’s report?
A3: ANS-1 | B3: Clients actively use online banking=COUNTIF(Dataset!N2:N350,Dataset!N335) | M3: =COUNTIF(Dataset!N2:N350,Dataset!N335) -> 182
B4: 50th percentile=PERCENTILE.INC(IF(Dataset!N2:N350="Active",Dataset!H2:H350),0.5) | M4: {=_xlfn.PERCENTILE.INC(IF(Dataset!N2:N350="Active",Dataset!H2:H350),0.5)} -> 60000
A6: Q2 | B6: Highest Loan Amount: The credit department at SwiftBank wants to know how many clients have taken out loans. Additionally, they need to identify the highest loan amount in the system. Can you find this information?
A7: ANS-2 | B7: clients who have taken loan=COUNTIF(Dataset!I2:I350,Dataset!I335) | M7: =COUNTIF(Dataset!I2:I350,Dataset!I335) -> 169
B8: the highest loan amount in the system=MAX(Dataset!J2:J350) | M8: =MAX(Dataset!J2:J350) -> 20000
A10: Q3 | B10: Non-Borrowers’ Smallest Balance: The bank’s savings team is conducting a study on customers who haven’t taken out any loans. As part of this, they need you to find the 3rd smallest account balance among these non-borrowers. Can you provide the data?
A11: ANS-3 | B11: the 3rd smallest account balance among non-borrowers=SMALL(UNIQUE(IF(Dataset!I2:I350="no",Dataset!G2:G350)),3) | M11: {=SMALL(_xlfn.UNIQUE(IF(Dataset!I2:I350="no",Dataset!G2:G350)),3)} -> 2200
A14: Q4 | B14: Female Clients’ Income: SwiftBank is analyzing the financial health of its female clients. Your task is to find the second-lowest annual income among all women with accounts at the bank. Can you find this information for the analysis?
A15: ANS=4 | B15: the second-lowest annual income among all women with accounts at the banK=SMALL(IF(Dataset!E2:E350="F",Dataset!H2:H350),2) | O15: {=SMALL(IF(Dataset!E2:E350="F",Dataset!H2:H350),2)} -> 45000
A17: Q6 | B17: Most Common Account Balance: The finance team wants to understand the common financial behaviors of clients. To assist, they’ve asked you to identify the most common account balance among all customers. Additionally, they need the average balance. Can you determine both?
A18: ANS=6 | B18: the most common account balance among all customers=MODE.MULT(Dataset!G2:G350) | L18: {=_xlfn.MODE.MULT(Dataset!G2:G350)} -> 4000
B19: average balance =AVERAGE(Dataset!G2:G350) | L19: =AVERAGE(Dataset!G2:G350) -> 6148.9971
A21: Q7 | B21: 75th Percentile Income and Balance: SwiftBank is working on offering high-end financial products and needs to identify the wealthier clients. Your task is to find the 75th percentile for both annual income and account balance. Can you provide this data?
A22: ANS=7 | B22: the 75th percentile for annual income =PERCENTILE.INC(Dataset!H2:H350,0.75) | K22: =_xlfn.PERCENTILE.INC(Dataset!H2:H350,0.75) -> 70000
B23: the 75th percentile for Account balance =PERCENTILE.INC(G2:G350,0.75) | K23: =_xlfn.PERCENTILE.INC(Dataset!G2:G350,0.75) -> 8000

Sheet HARD
B1: HARD
A2: Q1 | B2: Female Mutual Fund Investors: The investment team wants to focus on female clients who have invested in mutual funds and have a credit score above 500. Additionally, they want to know the highest account balance among these clients. Can you provide this report?
A3: ANS-1 | B3: female clients who have invested in mutual funds and have a credit score above 500 =MAXIFS(Dataset!G2:G350,Dataset!E2:E350,Dataset!E330,Dataset!L2:L350,Dataset!L334,Dataset!K2:K350,">500") | U3: =_xlfn.MAXIFS(Dataset!G2:G350,Dataset!E2:E350,Dataset!E330,Dataset!L2:L350,Dataset!L334,Dataset!K2:K350,">500") -> 15000
B4: COUNTIFS(Dataset!E2:E350, "F", Dataset!L2:L350, "Mutual Funds", Dataset!K2:K350, ">500") | N4: =COUNTIFS(Dataset!E2:E350, "F", Dataset!L2:L350, "Mutual Funds", Dataset!K2:K350, ">500") -> 87
A7: Q2 | B7: Highest Balance for Each Investment Type: The investment team is studying current trends across various investment types. Your task is to find the highest annual income for each type of investment (stocks, bonds, real estate, and mutual funds). Can you gather these insights?
A8: ANS-2 | B8: the highest annual income for each type of investment stocks=MAXIFS(Dataset!H2:H350,Dataset!L2:L350,Dataset!L2) | N8: =_xlfn.MAXIFS(Dataset!H2:H350,Dataset!L2:L350,Dataset!L2) -> 80000
B9: the highest annual income for each type of investment BONDS=MAXIFS(Dataset!H2:H350,Dataset!L2:L350,Dataset!L3) | N9: =_xlfn.MAXIFS(Dataset!H2:H350,Dataset!L2:L350,Dataset!L3) -> 77000
B10: the highest annual income for each type of investment real estate=MAXIFS(Dataset!H2:H350,Dataset!L2:L350,Dataset!L5) | N10: =_xlfn.MAXIFS(Dataset!H2:H350,Dataset!L2:L350,Dataset!L5) -> 74000
B11: the highest annual income for each type of investment mutual funds=MAXIFS(Dataset!H2:H350,Dataset!L2:L350,Dataset!L4) | N11: =_xlfn.MAXIFS(Dataset!H2:H350,Dataset!L2:L350,Dataset!L4) -> 85000
A14: Q3 | B14: Credit Card Offer Income Analysis: SwiftBank wants to analyze its credit card offers based on annual income. Your task is to find the highest annual income for clients using each type of credit card (premium, standard, or none). Also, how many clients haven’t accepted any credit card offers? Can you provide this breakdown?
A15: ANS-3 | B15: The highest annual income for clients using each type of credit card premium=MAXIFS(Dataset!H2:H350,Dataset!M2:M350,Dataset!M2) | P15: =_xlfn.MAXIFS(Dataset!H2:H350,Dataset!M2:M350,Dataset!M2) -> 82000
B16: The highest annual income for clients using each type of credit card standard=MAXIFS(Dataset!H2:H350,Dataset!M2:M350,Dataset!M3) | P16: =_xlfn.MAXIFS(Dataset!H2:H350,Dataset!M2:M350,Dataset!M3) -> 74000
B17: The highest annual income for clients using each type of credit card none=MAXIFS(Dataset!H2:H350,Dataset!M2:M350,Dataset!M4) | P17: =_xlfn.MAXIFS(Dataset!H2:H350,Dataset!M2:M350,Dataset!M4) -> 85000
A19: Q4 | B19: 20th Percentile for Mutual Fund Investors: Mutual fund investments are becoming increasingly popular. SwiftBank wants to calculate the 20th percentile of annual income among clients who have invested in mutual funds. Can you provide this analysis?
A20: ANS-4 | B20: the 20th percentile of annual income among clients who have invested in mutual funds.=PERCENTILE.INC(IF(Dataset!L2:L350="Mutual Funds",Dataset!G2:G350),0.2) | R20: {=_xlfn.PERCENTILE.INC(IF(Dataset!L2:L350="Mutual Funds",Dataset!G2:G350),0.2)} -> 2600
A22: Q5 | B22: Second Smallest Income for Female Clients: The finance department wants to dive deeper into the income levels of female account holders. They need you to identify the second smallest annual income among female clients. Can you find this value?
A23: ANS-5 | B23: Female account holders=COUNTIF(Dataset!E2:E350, "F") | I23: =COUNTIF(Dataset!E2:E350, "F") -> 170
B24: the second smallest annual income among female clients. =SMALL(IF(Dataset!E2:E350="F",Dataset!H2:H350),2) | M24: {=SMALL(IF(Dataset!E2:E350="F",Dataset!H2:H350),2)} -> 45000
A26: Q6 | B26: Savings Accounts Above the Median: SwiftBank is analyzing savings account holders and wants to know how many clients have an annual income above the median. Additionally, they want to know the highest annual income among these clients. Can you complete this analysis?
A27: ANS-6 | B27: COUNTIF(Dataset!F2:F350,"Savings") | G27: =COUNTIF(Dataset!F2:F350,"Savings") -> 160
B28: MEDIAN(Dataset!H2:H350) | G28: =MEDIAN(Dataset!H2:H350) -> 60000
B29: COUNTIFS(Dataset!F2:F350,"Savings",Dataset!H2:H350,">60000") | G29: =COUNTIFS(Dataset!F2:F350,"Savings",Dataset!H2:H350,">60000") -> 77
B30: MAXIFS(Dataset!H2:H350,Dataset!F2:F350,"Savings",Dataset!H2:H350,">60000") | G30: =_xlfn.MAXIFS(Dataset!H2:H350,Dataset!F2:F350,"Savings",Dataset!H2:H350,">60000") -> 80000
A32: Q7 | B32: Total Income and Largest Balance for Savings Account Holders: The bank is preparing a report on savings account holders. Your task is to calculate the total annual income for these clients and identify the largest account balance in this category. Can you help?
B33: total annual income for the savings account holders=SUMIF(Dataset!F2:F350,Dataset!F330,Dataset!H2:H350) | M33: =SUMIF(Dataset!F2:F350,Dataset!F330,Dataset!H2:H350) -> 9611000
B34: the largest account balance for the savings account=MAXIFS(Dataset!H2:H350,Dataset!F2:F350,Dataset!F340) | M34: =_xlfn.MAXIFS(Dataset!H2:H350,Dataset!F2:F350,Dataset!F340) -> 80000
